Workbook
Name X65X200: 'Ventas MELI'!$X$56
Name X65X200: 'Ventas Web'!#REF!
Name X65X200: 'Ventas pre diciembre'!$AC$65

Sheet Ventas pre diciembre
Y1: 0.15
A2: ESTADO | B2: Fecha | C2: Procedencia | D2: $ venta ML | E2: Nombre | G2: Telefono | H2: Producto | I2: Cantidad | J2: Venta | K2: FACTURÓ | L2: Cargo por venta | M2: Costo fijo | N2: "impuestos" | O2: Envio entró | P2: Envio salio | Q2: Envio quedó | R2: Costo | S2: Comision MP | T2: IIBB Tucuman | U2: Retencion SIRTAC | V2: IIBB CABA | W2: Ganancia | X2: MONOTRIBUTO | Y2: % a Brisa | AC2: Chocos Colonial Usados | AE2: NECESITO
B3: 45921 | C3: Mercado Libre | D3: 113000 | H3: Mini recuerdo | I3: 100 | J3: 77184 | W3: 45870 | Y3: =W3*$Y$1 -> 6880.5 | Z3: =SUM(Y3:Y9) -> 14292.9 | AR3: MELI | AS3: 0.01
B4: 25 | C4: IG | E4: Beatriz | H4: Choco Suelto | I4: 50 | J4: 23250 | W4: 7646 | Y4: =W4*$Y$1 -> 1146.9 | AR4: WEB | AS4: 0.1
B5: 45915 | C5: WPP | E5: Magali | H5: Cajita de 4 | I5: 15 | J5: 36112 | W5: 12225 | Y5: =W5*$Y$1 -> 1833.75 | AR5: IG | AS5: 0.1
B6: 45929 | C6: Pagina | E6: eugenia | H6: Cajita de 6 | I6: 20 | J6: 63745 | W6: =J6-(2310*20) -> 17545 | Y6: =W6*$Y$1 -> 2631.75 | AR6: OTRO | AS6: 0.05
B7: 45926 | C7: Mercado Libre | D7: 50500 | E7: Silvina edith espindola | H7: Cajita de 4 | I7: 15 | J7: 36746 | W7: 12000 | Y7: =W7*$Y$1 -> 1800
C8: Octubre
B9: 45931 | C9: WPP | E9: Valeria Limonoff | H9: Cajita de 4 | I9: 100 | J9: 216675 | W9: 66294 | AR9: FACTURADO | AS9: =SUM(J9:J26) -> 1936729.9 | AU9: =AS10*0.05 -> 34975.231
B10: 45931 | C10: otro | E10: Stefano | G10: 3416742265 | H10: Mini recuerdo | I10: 200 | J10: 145350 | W10: 69645 | Y10: =W10*$Y$8 -> 0 | Z10: =SUM(Y10:Y120) -> #REF! | AJ10: Choco Suelto | AK10: 294 | AR10: GANANCIA | AS10: =SUM(W9:W26)-W24 -> 699504.62
B11: 45933 | C11: otro | E11: Geraldine desconfiada | G11: 1123192733 | H11: Cajita de 4 | I11: 85 | J11: 203490 | W11: =J11-(1570.84*85) -> 69968.6 | Y11: =W11*$Y$8 -> 0 | AJ11: Mini Recuerdo | AK11: 327 | AU11: =AS9-AS10 -> 1237225.3
B12: 45933 | C12: Meli | E12: Monica | H12: Mini recuerdo/separadores | I12: 80 | J12: 64960 | W12: 32560 | Y12: =W12*$Y$8 -> 0 | AJ12: Tarjeta | AK12: 330
B13: 45936 | C13: Meli | D13: 113000 | E13: Nadia Staiano | H13: Mini recuerdo | I13: 100 | J13: 76950 | W13: 36600 | Y13: {=W13 * _xlfn.XLOOKUP(C13, {"MELI";"WEB";"IG";"OTRO"}, $AS$3:$AS$6)} -> 366 | AJ13: Cajita de 4 | AK13: 1443.5
B14: 45936 | C14: Meli | D14: 32000 | E14: Julia Sansone | H14: Cajita de 4 | I14: 10 | J14: 24000 | W14: 8150 | Y14: {=W14 * _xlfn.XLOOKUP(C14, {"MELI";"WEB";"IG";"OTRO"}, $AS$3:$AS$6)} -> 81.5 | AJ14: Cajita de 4 deluxe | AK14: 1499.86
B15: 45940 | C15: otro | E15: Geraldine desconfiada | G15: 1123192733 | H15: Stickers | I15: 85 | J15: 24000 | W15: =J15-(2079+3036) -> 18885 | Y15: {=W15 * _xlfn.XLOOKUP(C15, {"MELI";"WEB";"IG";"OTRO"}, $AS$3:$AS$6)} -> 944.25 | AJ15: D6 Classic | AK15: 2263.63
B16: 45944 | C16: Ig | E16: Brava | G16: 11 2472-6058 | H16: Chocos Sueltos | I16: 50 | J16: 22500 | W16: 7773 | Y16: {=W16 * _xlfn.XLOOKUP(C16, {"MELI";"WEB";"IG";"OTRO"}, $AS$3:$AS$6)} -> 777.3 | AJ16: D6 Deluxe | AK16: 2422
B17: 45944 | C17: IG | E17: Claudia Galeano | G17: 11 5629-1780 | H17: Mini Recuerdo | I17: 130 | J17: 111150 | W17: 65970 | Y17: {=W17 * _xlfn.XLOOKUP(C17, {"MELI";"WEB";"IG";"OTRO"}, $AS$3:$AS$6)} -> 6597 | AJ17: D6 Gold | AK17: 2384.8
C18: ig | E18: Cris | G18: 2235 22-6326 | H18: Caja 22 chocos | I18: 1 | J18: 13000 | W18: 5871 | Y18: {=W18 * _xlfn.XLOOKUP(C18, {"MELI";"WEB";"IG";"OTRO"}, $AS$3:$AS$6)} -> 587.1 | AJ18: Black | AK18: 2610
C19: ig | E19: =E18 -> Cris | G19: =G18 -> 2235 22-6326 | H19: Choco Cintas | I19: 30 | J19: 33000 | R19: 19710 | W19: =J19-R19 -> 13290 | Y19: {=W19 * _xlfn.XLOOKUP(C19, {"MELI";"WEB";"IG";"OTRO"}, $AS$3:$AS$6)} -> 1329 | AJ19: Señaladores | AK19: 440.7
C20: Meli | E20: Nadia Staiano | H20: Mini Recuerdo | I20: 100 | J20: 93196 | R20: 34754 | W20: =(J20-R20)-9500 -> 48942 | Y20: {=W20 * _xlfn.XLOOKUP(C20, {"MELI";"WEB";"IG";"OTRO"}, $AS$3:$AS$6)} -> 489.42 | AJ20: D2 | AK20: 1293
C21: Meli | E21: Alejandra Beatríz Vecci de Massolo | H21: Petit Box | I21: 10 | J21: 23385.47 | R21: 14190 | W21: =J21-R21 -> 9195.47 | Y21: {=W21 * _xlfn.XLOOKUP(C21, {"MELI";"WEB";"IG";"OTRO"}, $AS$3:$AS$6)} -> 91.9547 | AJ21: D2 moño | AK21: 1367
C22: Meli | E22: GEORGINA VANESA PORTUGAL | H22: Petit Box | I22: 10 | J22: =J21 -> 23385.47 | R22: =R21 -> 14190 | W22: =J22-R22 -> 9195.47 | Y22: {=W22 * _xlfn.XLOOKUP(C22, {"MELI";"WEB";"IG";"OTRO"}, $AS$3:$AS$6)} -> 91.9547 | AJ22: Vela 100cc
C23: meli | E23: Caja Forense de la pampa | G23: 2215 37-4454 | H23: Cajita Gold | I23: 65 | J23: 257985 | R23: =141765+5159+154.79 -> 147078.79 | T23: 154.79 | U23: 5159.7 | W23: =J23-R23 -> 110906.21 | Y23: {=W23 * _xlfn.XLOOKUP(C23, {"MELI";"WEB";"IG";"OTRO"}, $AS$3:$AS$6)} -> 1109.0621 | AJ23: Vela 200cc
C24: meli | E24: =E23 -> Caja Forense de la pampa | G24: =G23 -> 2215 37-4454 | H24: =H23 -> Cajita Gold | I24: =I23 -> 65 | J24: =J23 -> 257985 | R24: =R23 -> 147078.79 | T24: 309.58 | U24: 5159.7 | W24: =J24-R24 -> 110906.21 | Y24: {=W24 * _xlfn.XLOOKUP(C24, {"MELI";"WEB";"IG";"OTRO"}, $AS$3:$AS$6)} -> 1109.0621 | AJ24: caja 44 chocos | AK24: 12512
C25: web | E25: Carla | H25: Caja Deluxe | I25: 50 | J25: 247500 | R25: =123100 -> 123100 | S25: 18834.75 | T25: 61.88 | U25: 7425 | V25: 11137.5 | W25: =J25-R25-S25-T25-U25-V25 -> 86940.87 | X25: =W25*0.05 -> 4347.0435 | Y25: {=W25 * _xlfn.XLOOKUP(C25, {"MELI";"WEB";"IG";"OTRO"}, $AS$3:$AS$6)} -> 8694.087 | AC25: =I25*6 -> 300
C26: MELI | E26: Paula Bianchi | H26: Chocos Sueltos | I26: 200 | J26: 98218 | R26: 58900 | W26: =J26-R26 -> 39318 | X26: =W26*0.05 -> 1965.9 | Y26: {=W26 * _xlfn.XLOOKUP(C26, {"MELI";"WEB";"IG";"OTRO"}, $AS$3:$AS$6)} -> 393.18
C27: MELI | E27: Alejandra Leandro | H27: Mini recuerdo | I27: 100 | J27: 83841 | R27: 34754 | W27: =J27-R27 -> 49087 | X27: =W27*0.05 -> 2454.35 | Y27: {=W27 * _xlfn.XLOOKUP(C27, {"MELI";"WEB";"IG";"OTRO"}, $AS$3:$AS$6)} -> 490.87
B28: 45687 | C28: MELI | E28: Maria Marta derderian | H28: Choco Suelto | I28: 25 | J28: 14458.37 | K28: 20100 | O28: 7370.99 | R28: 7377.75 | W28: =J28-R28 -> 7080.62 | Y28: {=W28 * _xlfn.XLOOKUP(C28, {"MELI";"WEB";"IG";"OTRO"}, $AS$3:$AS$6)} -> 70.8062
B29: 45961 | C29: MELI | E29: Marisa Borello | H29: Cajas 6 choco | I29: 16 | J29: 76614.1 | K29: 92000 | R29: 37023.52 | W29: =J29-R29 -> 39590.58 | Y29: {=W29 * _xlfn.XLOOKUP(C29, {"MELI";"WEB";"IG";"OTRO"}, $AS$3:$AS$6)} -> 395.9058
C30: MELI | E30: Marisa Borello | H30: Cajas 6 choco | I30: 5 | J30: 24000 | R30: 11569.85 | T30: 14.4 | U30: 480 | W30: =J30-SUM(R30:V30) -> 11935.75 | Y30: {=W30 * _xlfn.XLOOKUP(C30, {"MELI";"WEB";"IG";"OTRO"}, $AS$3:$AS$6)} -> 119.3575
D31: Noviembre | Y31: BRISA | Z31: =SUM(Y76:Y200)-4000 -> #REF! | AC31: =SUM(AC32:AC188) -> #REF! | AD31: =AC31/50 -> #REF! | AF31: =SUM(W32:W53) -> 481858.12
B32: 45964 | C32: IG | D32: Completado | E32: Antonella Tunut | G32: 93586016473 | H32: Choco Suelto | I32: 100 | J32: =K32-T32-U32 -> 67335.57 | K32: 68794 | R32: 29500 | T32: 82.55 | U32: 1375.88 | W32: =J32-SUM(R32:V32) -> 36377.14 | X32: =W32*0.05 -> 1818.857 | Y32: {=W32 * _xlfn.XLOOKUP(C32, {"MELI";"WEB";"IG";"OTRO"}, $AS$3:$AS$6)} -> 3637.714 | AA32: Completado
B33: 45932 | C33: MELI | D33: Completado | E33: The park | H33: D6 Gold | I33: 8 | J33: 35286.6 | K33: 53600 | R33: 18511 | W33: =J33-SUM(R33:V33) -> 16775.6 | X33: =W33*0.05 -> 838.78 | Y33: {=W33 * _xlfn.XLOOKUP(C33, {"MELI";"WEB";"IG";"OTRO"}, $AS$3:$AS$6)} -> 167.756 | AA33: Completado
B34: 45964 | C34: MELI | D34: Completado | E34: Romina Rojas | H34: D6 Gold | I34: 25 | J34: 115465 | K34: 140000 | R34: 57849.25 | W34: =J34-SUM(R34:V34) -> 57615.75 | X34: =W34*0.05 -> 2880.7875 | Y34: {=W34 * _xlfn.XLOOKUP(C34, {"MELI";"WEB";"IG";"OTRO"}, $AS$3:$AS$6)} -> 576.1575 | AA34: Completado
B35: 45964 | C35: MELI | D35: Completado | E35: Paula Bianchi | F35: fusion | H35: Choco Suelto | I35: 200 | J35: 113893.26 | K35: 145000 | R35: 59022 | W35: =J35-SUM(R35:V35) -> 54871.26 | X35: =W35*0.05 -> 2743.563 | Y35: {=W35 * _xlfn.XLOOKUP(C35, {"MELI";"WEB";"IG";"OTRO"}, $AS$3:$AS$6)} -> 548.7126 | AA35: Completado
B36: 45964 | C36: OTRO | D36: Completado | E36: Jennifer Ayala | F36: 15 cenicienta | G36: +54 9 11 4494-4551 | H36: D6 Gold | I36: 25 | J36: =K36-T36-U36-O36 -> 107479.32 | K36: 118900 | O36: 8900 | R36: 57849.25 | T36: 142.68 | U36: 2378 | W36: =J36-R36 -> 49630.07 | X36: =W36*0.05 -> 2481.5035 | Y36: {=W36 * _xlfn.XLOOKUP(C36, {"MELI";"WEB";"IG";"OTRO"}, $AS$3:$AS$6)} -> 2481.5035 | AA36: Falta
B37: 45966 | C37: WEB | D37: Completado | E37: Federico Cunioli | F37: Anuncio nacimiento | G37: +54 9 11 5176-0510 | H37: D6 Gold | I37: 10 | J37: =K37-O37-T37-U37 -> 42953.08 | K37: 54100 | O37: 10000 | R37: 23139.7 | T37: 64.92 | U37: 1082 | W37: =J37-SUM(R37:V37) -> 18666.46 | X37: =W37*0.05 -> 933.323 | Y37: {=W37 * _xlfn.XLOOKUP(C37, {"MELI";"WEB";"IG";"OTRO"}, $AS$3:$AS$6)} -> 1866.646 | AA37: Completado
C38: OTRO | D38: Completado | E38: Transf envio correo | G38: antonella tunut | K38: 1600 | W38: =J38-R38 -> 0 | X38: =W38*0.05 -> 0 | Y38: {=W38 * _xlfn.XLOOKUP(C38, {"MELI";"WEB";"IG";"OTRO"}, $AS$3:$AS$6)} -> 0 | AC38: =IF(OR(H38="D6 Classic",H38="D6 Deluxe",H38="D6 Gold"),6*I38, IF(OR(H38="D2",H38="D2 moño"),2*I38, IF(H38="Cajita de 4",4*I38, IF(OR(H38="Mini Recuerdo",H38="Choco Cintas",H38="Choco Suelto"),1*I38, IF(H38="Caja 22 Chocos",22*I38, IF(H38="Caja 44 Chocos",44*I38,""))))))
B39: 45968 | C39: WEB | D39: Completado | E39: Mariana Seren | F39: La de 90 años | G39: 11 5484-5699 | H39: D2 moño | I39: 50 | J39: =K39-R39-T39-U39-8000 -> 81711.87 | K39: 165242 | R39: 72027 | T39: 198.29 | U39: 3304.84 | W39: =J39-SUM(R39:V39) -> 6181.74 | X39: =W39*0.05 -> 309.087 | Y39: {=W39 * _xlfn.XLOOKUP(C39, {"MELI";"WEB";"IG";"OTRO"}, $AS$3:$AS$6)} -> 618.174 | AC39: =IF(OR(H39="D6 Classic",H39="D6 Deluxe",H39="D6 Gold"),6*I39, IF(OR(H39="D2",H39="D2 moño"),2*I39, IF(H39="Cajita de 4",4*I39, IF(OR(H39="Mini Recuerdo",H39="Choco Cintas",H39="Choco Suelto"),1*I39, IF(H39="Caja 22 Chocos",22*I39, IF(H39="Caja 44 Chocos",44*I39,"")))))) -> 100
B40: 45968 | C40: MELI | D40: Completado | E40: Alejandra Patricia | G40: 11 5122-2668 | H40: Mini Recuerdo | I40: 50 | J40: =K40-O40 -> 45742 | K40: 54584 | O40: 8842 | R40: =17377+R41 -> 22385.86 | T40: 65.5 | U40: 1091.68 | W40: =J40-SUM(R40:V40) -> 22198.96 | X40: =W40*0.05 -> 1109.948 | Y40: {=W40 * _xlfn.XLOOKUP(C40, {"MELI";"WEB";"IG";"OTRO"}, $AS$3:$AS$6)} -> 221.9896 | AC40: =IF(OR(H40="D6 Classic",H40="D6 Deluxe",H40="D6 Gold"),6*I40, IF(OR(H40="D2",H40="D2 moño"),2*I40, IF(H40="Cajita de 4",4*I40, IF(OR(H40="Mini Recuerdo",H40="Choco Cintas",H40="Choco Suelto"),1*I40, IF(H40="Caja 22 Chocos",22*I40, IF(H40="Caja 44 Chocos",44*I40,"")))))) -> 50
...

Sheet Gomitas
F3: x gr | H3: Picada
C4: Conitos | D4: 1000 | E4: 7494 | F4: =E4/D4 -> 7.494 | H4: 85 | I4: =F4*$H$4 -> 636.99
C5: Anillos | D5: 1000 | E5: 8795 | F5: =E5/D5 -> 8.795 | H5: 6 | I5: =F5*$H$4 -> 747.575
C6: Redonditos | D6: 1000 | E6: 9999 | F6: =E6/D6 -> 9.999 | H6: =H4*H5 -> 510 | I6: =F6*$H$4 -> 849.915
C7: Gusanitos | D7: 500 | E7: 7400 | F7: =E7/D7 -> 14.8 | I7: =F7*$H$4 -> 1258
C8: Ositos | D8: 500 | E8: 5123 | F8: =E8/D8 -> 10.246 | I8: =F8*$H$4 -> 870.91
C9: Moritas | D9: 500 | E9: 5800 | F9: =E9/D9 -> 11.6 | I9: =F9*$H$4 -> 986
I10: =SUM(I4:I9) -> 5349.39

Sheet Estampitas
N3: 0.1 | O3: 0.08
N4: 0.09 | O4: 0.06
N5: =N4+N3 -> 0.19 | O5: =O4+O3 -> 0.14 | R5: Descuento | S5: Descuento | T5: Descuento
B6: Doble base telada detalles foil | C6: Base | D6: Estampa | E6: Foil | F6: Impresión | G6: Pegamento | K6: Costo total | L6: Ganancia | M6: Total | N6: MP | O6: Ganan MP | R6: 0.05 | S6: 0.1 | T6: 0.15
C7: =Insumos!G12/4 -> 101.75 | D7: =Insumos!G18/6 -> 10.893333 | E7: =Insumos!G15/6 -> 48.666667 | F7: 100 | G7: 100 | K7: =SUM(C7:J7) -> 361.31 | L7: 500 | M7: =L7+K7 -> 861.31 | N7: =(L7+K7)+((K7+L7)*(N5)) -> 1024.9589 | O7: =N7-(N7*O5)-K7 -> 520.15465 | R7: 50 | S7: 100 | T7: 200
R8: Costo total | S8: Costo total | T8: Costo total
R9: =K7*R7 -> 18065.5 | S9: =K7*S7 -> 36131 | T9: =K9*T7 -> 0
N10: Transf | R10: MP | S10: MP | T10: MP
N11: =N7-(N7*R18) -> 922.46301 | R11: =($N7*R7)-(($N7*R7)*R6) -> 48685.548 | S11: =($N7*S7)-(($N7*S7)*S6) -> 92246.301 | T11: =($N7*T7)-(($N7*T7)*T6) -> 174243.01
N12: G. Transf | R12: =R11/R7 -> 973.71095 | S12: =S11/S7 -> 922.46301 | T12: =T11/T7 -> 871.21506
N13: =(N11-(N11*O4))-K7 -> 505.80523 | R13: Ganancia MP | S13: Ganancia MP | T13: Ganancia MP
R14: =(R11-R9)-(R11*$O$27) -> 30620.048 | S14: =(S11-S9)-(S11*$O$27) -> 56115.301 | T14: =(T11-T9)-(T11*$O$27) -> 174243.01
R15: =R14/R7 -> 612.40095 | S15: =S14/S7 -> 561.15301 | T15: =T14/T7 -> 871.21506
R16: Transf | S16: Transf | T16: Transf
R17: =R11-(R11*R18) -> 43816.993 | S17: =S11-(S11*S18) -> 83021.671 | T17: =T11-(T11*T18) -> 156818.71
N18: 0.1 | O18: 0.08 | R18: 0.1 | S18: 0.1 | T18: 0.1
N19: 0.09 | O19: 0.06 | R19: =R17/R7 -> 876.33986 | S19: =S17/S7 -> 830.21671 | T19: =T17/T7 -> 784.09356
N20: =N19+N18 -> 0.19 | O20: =O19+O18 -> 0.14 | R20: Ganancia trans | S20: Ganancia trans | T20: Ganancia trans
B21: Estampa cruz madera | C21: Cruz | D21: tarjeta frontal | E21: Base | F21: Borla | G21: Impresión | K21: Costo total | L21: Ganancia | M21: Total | N21: MP | O21: Ganan MP | R21: =R17-(R17*$O$26)-R9 -> 25751.493 | S21: =S17-(S17*$O$26)-S9 -> 46890.671 | T21: =T17-(T17*$O$26)-T9 -> 156818.71
C22: =Insumos!R18 -> 95.275 | D22: =Insumos!G18/5 -> 13.072 | E22: =Insumos!G18/4 -> 16.34 | F22: =Insumos!R15 -> 347.8 | G22: 100 | K22: =SUM(C22:J22) -> 572.487 | L22: 500 | M22: =L22+K22 -> 1072.487 | N22: =(L22+K22)+((K22+L22)*(N20)) -> 1276.2595 | O22: =N22-(N22*O20)-K22 -> 525.0962 | R22: =R21/R7 -> 515.02986 | S22: =S21/S7 -> 468.90671 | T22: =T21/T7 -> 784.09356
N25: Transf
N26: =N22-(N22*R33) -> 1276.2595
N27: G. Transf
N28: =(N26-(N26*O19))-K22 -> 627.19696
N32: 0.1 | O32: 0.08
N33: 0.09 | O33: 0.06
N34: =N33+N32 -> 0.19 | O34: =O33+O32 -> 0.14
B35: Estampa Fondo Craft | D35: tarjeta frontal | E35: Base | F35: Cinta | G35: Impresión | K35: Costo total | L35: Ganancia | M35: Total | N35: MP | O35: Ganan MP
D36: =Insumos!G21/6 -> 63.375 | E36: =Insumos!G42/6 -> 24.283333 | F36: =Insumos!AK11*16 -> 79.296 | G36: 50 | K36: =SUM(C36:J36) -> 216.95433 | L36: 500 | M36: =L36+K36 -> 716.95433 | N36: =(L36+K36)+((K36+L36)*(N34)) -> 853.17566 | O36: =N36-(N36*O34)-K36 -> 516.77673
N39: Transf
N40: =N36-(N36*R47) -> 853.17566
N41: G. Transf
N42: =(N40-(N40*O33))-K36 -> 585.03078
C59: enero
C60: Febrero
C61: marzo
C62: abril
C63: mayo
C64: junio | D64: 325493.64
C65: julio | D65: 410590.9 | E65: =D65-D64 -> 85097.26
...

Sheet Tejidos
N3: 0.1 | P3: 0.08
N4: 0.09 | P4: 0.06
N5: =N4+N3 -> 0.19 | P5: =P4+P3 -> 0.14 | S5: Descuento | T5: Descuento | U5: Descuento
B6: Infinito + Tarjeta + Flores | C6: Cord exter | D6: Cord medio | E6: Cordon nudo | F6: Tarjeta | G6: Bolsa | H6: Gancho | I6: Florcitas | K6: Costo total | L6: Ganancia | M6: Total | N6: MP | O6: MP | P6: Ganan MP | S6: 0.05 | T6: 0.1 | U6: 0.15
C7: =(Insumos!V5*70)*2 -> 128.87 | D7: =Insumos!V5*35 -> 32.2175 | E7: =Insumos!V5*15 -> 13.8075 | F7: =Insumos!G12/3 -> 135.66667 | G7: =Insumos!AA8 -> 34.66 | H7: =Insumos!V11 -> 329.9 | I7: 200 | K7: =SUM(C7:J7) -> 875.12167 | L7: 2000 | M7: =L7+K7 -> 2875.1217 | N7: =ROUND(O7/50,0)*50 -> 3400 | O7: =(L7+K7)+((K7+L7)*(N5)) -> 3421.3948 | P7: =N7-(N7*P5)-K7 -> 2048.8783 | S7: 50 | T7: 100 | U7: 200
S8: Costo total | T8: Costo total | U8: Costo total
S9: =K7*S7 -> 43756.083 | T9: =K7*T7 -> 87512.167 | U9: =K9*U7 -> 0
N10: Transf | S10: MP | T10: MP | U10: MP
N11: =N7-(N7*S18) -> 3060 | S11: =($N7*S7)-(($N7*S7)*S6) -> 161500 | T11: =($N7*T7)-(($N7*T7)*T6) -> 306000 | U11: =($N7*U7)-(($N7*U7)*U6) -> 578000
L12: , | N12: G. Transf | S12: =S11/S7 -> 3230 | T12: =T11/T7 -> 3060 | U12: =U11/U7 -> 2890
N13: =(N11-(N11*P4))-K7 -> 2001.2783 | S13: Ganancia MP | T13: Ganancia MP | U13: Ganancia MP
S14: =(S11-S9)-(S11*$P$27) -> 104823.92 | T14: =(T11-T9)-(T11*$P$27) -> 194007.83 | U14: =(U11-U9)-(U11*$P$27) -> 531760
S15: =S14/S7 -> 2096.4783 | T15: =T14/T7 -> 1940.0783 | U15: =U14/U7 -> 2658.8
S16: Transf | T16: Transf | U16: Transf
S17: =S11-(S11*S18) -> 145350 | T17: =T11-(T11*T18) -> 275400 | U17: =U11-(U11*U18) -> 520200
S18: 0.1 | T18: 0.1 | U18: 0.1
S19: =S17/S7 -> 2907 | T19: =T17/T7 -> 2754 | U19: =U17/U7 -> 2601
S20: Ganancia trans | T20: Ganancia trans | U20: Ganancia trans
S21: =S17-(S17*$P$26)-S9 -> 101593.92 | T21: =T17-(T17*$P$26)-T9 -> 187887.83 | U21: =U17-(U17*$P$26)-U9 -> 520200
S22: =S21/S7 -> 2031.8783 | T22: =T21/T7 -> 1878.8783 | U22: =U21/U7 -> 2601
N27: 0.1 | P27: 0.08
N28: 0.09 | P28: 0.06
N29: =N28+N27 -> 0.19 | P29: =P28+P27 -> 0.14 | S29: Descuento | T29: Descuento | U29: Descuento
B30: Colgante tejido + tarjeta | C30: Cord exter | D30: Cord medio | E30: Cordon nudo | F30: Tarjeta | G30: Bolsa | H30: Argolla | K30: Costo total | L30: Ganancia | M30: Total | N30: MP | O30: MP | P30: Ganan MP | S30: 0.05 | T30: 0.1 | U30: 0.15
C31: =C7 -> 128.87 | D31: =D7 -> 32.2175 | E31: =E7 -> 13.8075 | F31: =Insumos!G12/3 -> 135.66667 | G31: =Insumos!AA8 -> 34.66 | H31: =Insumos!V8 -> 51.85 | K31: =SUM(C31:J31) -> 397.07167 | L31: 1500 | M31: =L31+K31 -> 1897.0717 | N31: =ROUND(O31/50,0)*50 -> 2250 | O31: =(L31+K31)+((K31+L31)*(N29)) -> 2257.5153 | P31: =N31-(N31*P29)-K31 -> 1537.9283 | S31: 50 | T31: 100 | U31: 200
S32: Costo total | T32: Costo total | U32: Costo total
S33: =K31*S31 -> 19853.583 | T33: =K31*T31 -> 39707.167 | U33: =K33*U31 -> 0
N34: Transf | S34: MP | T34: MP | U34: MP
N35: =N31-(N31*S42) -> 2025 | S35: =($N31*S31)-(($N31*S31)*S30) -> 106875 | T35: =($N31*T31)-(($N31*T31)*T30) -> 202500 | U35: =($N31*U31)-(($N31*U31)*U30) -> 382500
N36: G. Transf | S36: =S35/S31 -> 2137.5 | T36: =T35/T31 -> 2025 | U36: =U35/U31 -> 1912.5
N37: =(N35-(N35*P28))-K31 -> 1506.4283 | S37: Ganancia MP | T37: Ganancia MP | U37: Ganancia MP
S38: =(S35-S33)-(S35*$P$27) -> 78471.417 | T38: =(T35-T33)-(T35*$P$27) -> 146592.83 | U38: =(U35-U33)-(U35*$P$27) -> 351900
S39: =S38/S31 -> 1569.4283 | T39: =T38/T31 -> 1465.9283 | U39: =U38/U31 -> 1759.5
S40: Transf | T40: Transf | U40: Transf
S41: =S35-(S35*S42) -> 96187.5 | T41: =T35-(T35*T42) -> 182250 | U41: =U35-(U35*U42) -> 344250
S42: 0.1 | T42: 0.1 | U42: 0.1
S43: =S41/S31 -> 1923.75 | T43: =T41/T31 -> 1822.5 | U43: =U41/U31 -> 1721.25
S44: Ganancia trans | T44: Ganancia trans | U44: Ganancia trans
S45: =S41-(S41*$P$26)-S33 -> 76333.917 | T45: =T41-(T41*$P$26)-T33 -> 142542.83 | U45: =U41-(U41*$P$26)-U33 -> 344250
S46: =S45/S31 -> 1526.6783 | T46: =T45/T31 -> 1425.4283 | U46: =U45/U31 -> 1721.25
...

Sheet Georgalos
C3: Georgalos | L3: 0.1 | N3: 0.08
L4: 0.09 | N4: 0.06
L5: =L4+L3 -> 0.19 | N5: =N4+N3 -> 0.14 | P5: Descuento | Q5: Descuento | R5: Descuento | S5: Descuento | T5: Descuento | U5: Descuento
A6: 2 | B6: Caja de 2 | C6: Choco | D6: Eti choco | E6: Eti caja | F6: Caja | G6: Extra Con Foil | I6: Costo total | J6: Ganancia | K6: Total | L6: MP | M6: MP | N6: Ganan MP | P6: 0 | Q6: 0.05 | R6: 0.07 | S6: 0.09 | T6: 0.11 | U6: 0.13
C7: =Insumos!C16*2 -> 782.4 | D7: =(Insumos!G6/5) -> 47.984 | E7: =Insumos!G6/6 -> 39.986667 | F7: =Insumos!N36 -> 365 | G7: =Insumos!G15/5 -> 58.4 | I7: =SUM(B7:H7) -> 1293.7707 | J7: =K7-I7 -> 2587.5413 | K7: =I7*3 -> 3881.312 | L7: =ROUND(M7/50,0)*50 -> 4600 | M7: =(J7+I7)+((I7+J7)*(L5)) -> 4618.7613 | N7: =(L7-(L7*N5))-I7 -> 2662.2293 | P7: 50 | Q7: 100 | R7: 200 | S7: 500 | T7: 1000 | U7: 2000
P8: Costo total | Q8: Costo total | R8: Costo total | S8: Costo total | T8: Costo total | U8: Costo total
B9: 100 | F9: =Insumos!N39 -> 312.075 | I9: =C7+D7+E7+F9 -> 1182.4457 | K9: =I9+J7 -> 3769.987 | P9: =I7*P7 -> 64688.533 | Q9: =I9*Q7 -> 118244.57 | R9: =$I$9*R7 -> 236489.13 | S9: =$I$9*S7 -> 591222.83 | T9: =$I$9*T7 -> 1182445.7 | U9: =$I$9*U7 -> 2364891.3
L10: Transf | P10: MP | Q10: MP | R10: MP | S10: MP | T10: MP | U10: MP
L11: =L7-(L7*P18) -> 4140 | P11: =($L7*P7)-(($L7*P7)*P6) -> 230000 | Q11: =($L7*Q7)-(($L7*Q7)*Q6) -> 437000 | R11: =($L7*R7)-(($L7*R7)*R6) -> 855600 | S11: =($L7*S7)-(($L7*S7)*S6) -> 2093000 | T11: =($L7*T7)-(($L7*T7)*T6) -> 4094000 | U11: =($L7*U7)-(($L7*U7)*U6) -> 8004000
L12: G. Transf | P12: =P11/P7 -> 4600 | Q12: =Q11/Q7 -> 4370 | R12: =R11/R7 -> 4278 | S12: =S11/S7 -> 4186 | T12: =T11/T7 -> 4094 | U12: =U11/U7 -> 4002
L13: =(L11-(L11*N4))-I7 -> 2597.8293 | P13: G. MP | Q13: G. MP | R13: G. MP | S13: G. MP | T13: G. MP | U13: G. MP
P14: =(P11-P9)-(P11*$N$5) -> 133111.47 | Q14: =(Q11-Q9)-(Q11*$N$5) -> 257575.43 | R14: =(R11-R9)-(R11*$N$5) -> 499326.87 | S14: =(S11-S9)-(S11*$N$5) -> 1208757.2 | T14: =(T11-T9)-(T11*$N$5) -> 2338394.3 | U14: =(U11-U9)-(U11*$N$5) -> 4518548.7
P15: =P14/P7 -> 2662.2293 | Q15: =Q14/Q7 -> 2575.7543 | R15: =R14/R7 -> 2496.6343 | S15: =S14/S7 -> 2417.5143 | T15: =T14/T7 -> 2338.3943 | U15: =U14/U7 -> 2259.2743
P16: Transf | Q16: Transf | R16: Transf | S16: Transf | T16: Transf | U16: Transf
P17: =P11-(P11*P18) -> 207000 | Q17: =Q11-(Q11*Q18) -> 393300 | R17: =R11-(R11*R18) -> 770040 | S17: =S11-(S11*S18) -> 1883700 | T17: =T11-(T11*T18) -> 3684600 | U17: =U11-(U11*U18) -> 7203600
P18: 0.1 | Q18: 0.1 | R18: 0.1 | S18: 0.1 | T18: 0.1 | U18: 0.1
P19: =P17/P7 -> 4140 | Q19: =Q17/Q7 -> 3933 | R19: =R17/R7 -> 3850.2 | S19: =S17/S7 -> 3767.4 | T19: =T17/T7 -> 3684.6 | U19: =U17/U7 -> 3601.8
P20: G. Transf | Q20: G. Transf | R20: G. Transf | S20: G. Transf | T20: G. Transf | U20: G. Transf
P21: =P17-(P17*$N$4)-P9 -> 129891.47 | Q21: =Q17-(Q17*$N$4)-Q9 -> 251457.43 | R21: =R17-(R17*$N$4)-R9 -> 487348.47 | S21: =S17-(S17*$N$4)-S9 -> 1179455.2 | T21: =T17-(T17*$N$4)-T9 -> 2281078.3 | U21: =U17-(U17*$N$4)-U9 -> 4406492.7
P22: =P21/P7 -> 2597.8293 | Q22: =Q21/Q7 -> 2514.5743 | R22: =R21/R7 -> 2436.7423 | S22: =S21/S7 -> 2358.9103 | T22: =T21/T7 -> 2281.0783 | U22: =U21/U7 -> 2203.2463
L27: 0.1 | N27: 0.08
L28: 0.09 | N28: 0.06
L29: =L28+L27 -> 0.19 | N29: =N28+N27 -> 0.14 | P29: Descuento | Q29: Descuento | R29: Descuento | S29: Descuento | T29: Descuento | U29: Descuento
B30: Caja de 2 Moño | C30: Choco | D30: Eti choco | E30: Eti Caja | F30: Caja | G30: Moño | I30: Costo total | J30: Ganancia | K30: Total | L30: MP | M30: MP | N30: Ganan MP | P30: 0 | Q30: 0.05 | R30: 0.07 | S30: 0.09 | T30: 0.11 | U30: 0.13
C31: =C7 -> 782.4 | D31: =D7 -> 47.984 | E31: =E7 -> 39.986667 | F31: =F7 -> 365 | G31: =Insumos!R9*70 -> 132.16 | I31: =SUM(B31:H31) -> 1367.5307 | J31: =K31-I31 -> 3008.5675 | K31: =I31*3.2 -> 4376.0981 | L31: =ROUND(M31/50,0)*50 -> 5200 | M31: =(J31+I31)+((I31+J31)*(L29)) -> 5207.5568 | N31: =(L31-(L31*N29))-I31 -> 3104.4693 | P31: 50 | Q31: 100 | R31: 200 | S31: 500 | T31: 1000 | U31: 2000
P32: Costo total | Q32: Costo total | R32: Costo total | S32: Costo total | T32: Costo total | U32: Costo total
B33: 100 | C33: =C31 -> 782.4 | D33: =D31 -> 47.984 | E33: =E31 -> 39.986667 | F33: =Insumos!N39 -> 312.075 | G33: =G31 -> 132.16 | I33: =C33+D33+E33+F33+G33 -> 1314.6057 | K33: =I33+J31 -> 4323.1731 | P33: =I31*P31 -> 68376.533 | Q33: =I33*Q31 -> 131460.57 | R33: =$I$33*R31 -> 262921.13 | S33: =$I$33*S31 -> 657302.83 | T33: =$I$33*T31 -> 1314605.7 | U33: =$I$33*U31 -> 2629211.3
L34: Transf | P34: MP | Q34: MP | R34: MP | S34: MP | T34: MP | U34: MP
L35: =L31-(L31*Q42) -> 4680 | P35: =($L31*P31)-(($L31*P31)*P30) -> 260000 | Q35: =($L31*Q31)-(($L31*Q31)*Q30) -> 494000 | R35: =($L31*R31)-(($L31*R31)*R30) -> 967200 | S35: =($L31*S31)-(($L31*S31)*S30) -> 2366000 | T35: =($L31*T31)-(($L31*T31)*T30) -> 4628000 | U35: =($L31*U31)-(($L31*U31)*U30) -> 9048000
L36: G. Transf | P36: =P35/P31 -> 5200 | Q36: =Q35/Q31 -> 4940 | R36: =R35/R31 -> 4836 | S36: =S35/S31 -> 4732 | T36: =T35/T31 -> 4628 | U36: =U35/U31 -> 4524
L37: =(L35-(L35*N28))-I31 -> 3031.6693 | P37: G. MP | Q37: G. MP | R37: G. MP | S37: G. MP | T37: G. MP | U37: G. MP
P38: =(P35-P33)-(P35*$N$5) -> 155223.47 | Q38: =(Q35-Q33)-(Q35*$N$5) -> 293379.43 | R38: =(R35-R33)-(R35*$N$5) -> 568870.87 | S38: =(S35-S33)-(S35*$N$5) -> 1377457.2 | T38: =(T35-T33)-(T35*$N$5) -> 2665474.3 | U38: =(U35-U33)-(U35*$N$5) -> 5152068.7
P39: =P38/P31 -> 3104.4693 | Q39: =Q38/Q31 -> 2933.7943 | R39: =R38/R31 -> 2844.3543 | S39: =S38/S31 -> 2754.9143 | T39: =T38/T31 -> 2665.4743 | U39: =U38/U31 -> 2576.0343
P40: Transf | Q40: Transf | R40: Transf | S40: Transf | T40: Transf | U40: Transf
P41: =P35-(P35*P42) -> 234000 | Q41: =Q35-(Q35*Q42) -> 444600 | R41: =R35-(R35*R42) -> 870480 | S41: =S35-(S35*S42) -> 2129400 | T41: =T35-(T35*T42) -> 4165200 | U41: =U35-(U35*U42) -> 8143200
P42: 0.1 | Q42: 0.1 | R42: 0.1 | S42: 0.1 | T42: 0.1 | U42: 0.1
P43: =P41/P31 -> 4680 | Q43: =Q41/Q31 -> 4446 | R43: =R41/R31 -> 4352.4 | S43: =S41/S31 -> 4258.8 | T43: =T41/T31 -> 4165.2 | U43: =U41/U31 -> 4071.6
P44: G. Transf | Q44: G. Transf | R44: G. Transf | S44: G. Transf | T44: G. Transf | U44: G. Transf
P45: =P41-(P41*$N$4)-P33 -> 151583.47 | Q45: =Q41-(Q41*$N$4)-Q33 -> 286463.43 | R45: =R41-(R41*$N$4)-R33 -> 555330.07 | S45: =S41-(S41*$N$4)-S33 -> 1344333.2 | T45: =T41-(T41*$N$4)-T33 -> 2600682.3 | U45: =U41-(U41*$N$4)-U33 -> 5025396.7
P46: =P45/P31 -> 3031.6693 | Q46: =Q45/Q31 -> 2864.6343 | R46: =R45/R31 -> 2776.6503 | S46: =S45/S31 -> 2688.6663 | T46: =T45/T31 -> 2600.6823 | U46: =U45/U31 -> 2512.6983
...

Sheet Ventas Web
W1: 0.15
A2: ESTADO | B2: Fecha | C2: Procedencia | D2: $ venta ML | E2: Nombre | G2: Telefono | H2: Producto | I2: Cantidad | J2: Modo pago | L2: Venta | M2: FACTURÓ | N2: Envio | P2: Costo | Q2: Comision MP | R2: 1er Impuesto 0,06 | S2: 2do impuesto 2% | T2: Ganancia | U2: AUTO | V2: MONOTRIBUTO | W2: BRISA
C3: MELI | E3: Diciembre | V3: =T3*0.05 -> 0 | X3: =SUM(W5:W22) -> 13214.279 | Y3: =X3+'Ventas MELI'!U3 -> 24232.148
C4: WEB | D4: Completado | E4: Ariela fefer | H4: Choco suelto +200 | I4: 200 | K4: DECOYA | L4: 112860 | M4: 122860 | N4: =M4-L4 -> 10000 | P4: =_xlfn.XLOOKUP(H4, AA:AA, AB:AB) * I4 -> 58800 | R4: =M4*0.0006 -> 73.716 | S4: =M4*0.02 -> 2457.2 | T4: =L4-P4-Q4-R4-S4 -> 51529.084 | U4: =IF(K4="CORREO",0,N4) -> 10000 | V4: =T4*0.05 -> 2576.4542 | W4: =T4*0.05 -> 2576.4542
C5: WEB | E5: Anabella Silvia chal | I5: 1 | K5: CORREO | L5: 15000 | M5: 15000 | N5: =M5-L5 -> 0 | P5: 11000 | R5: =M5*0.0006 -> 9 | S5: =M5*0.02 -> 300 | T5: =L5-P5-Q5-R5-S5 -> 3691 | U5: =IF(K5="CORREO",0,N5) -> 0 | V5: =T5*0.05 -> 184.55 | W5: =T5*0.05 -> 184.55 | AD5: Credito | AE5: Transf
C6: WEB | E6: Daniela Gomez | H6: Mini Recuerdo | I6: 20 | K6: CORREO | L6: 17100 | M6: 28400 | N6: =M6-L6 -> 11300 | P6: =_xlfn.XLOOKUP(H6, AA:AA, AB:AB) * I6 -> 6540 | R6: =M6*0.0006 -> 17.04 | S6: =M6*0.02 -> 568 | T6: =L6-P6-Q6-R6-S6 -> 9974.96 | U6: =IF(K6="CORREO",0,N6) -> 0 | V6: =T6*0.05 -> 498.748 | W6: =T6*0.05 -> 498.748 | AA6: Choco Suelto | AB6: 294 | AD6: 660 | AE6: =AD6-(AD6*0.1) -> 594
E7: Florencia sufi | H7: Mini Recuerdo | I7: 110 | K7: RETIRO | L7: 87318 | M7: 87318 | N7: =M7-L7 -> 0 | P7: =_xlfn.XLOOKUP(H7, AA:AA, AB:AB) * I7 -> 35970 | R7: =M7*0.0006 -> 52.3908 | S7: =M7*0.02 -> 1746.36 | T7: =L7-P7-Q7-R7-S7 -> 49549.249 | U7: =IF(K7="CORREO",0,N7) -> 0 | V7: =T7*0.05 -> 2477.4625 | W7: =T7*0.05 -> 2477.4625
E8: Florencia Franco | H8: Choco Suelto | I8: 50 | K8: DECOYA | L8: 29700 | M8: 39700 | N8: =M8-L8 -> 10000 | P8: =_xlfn.XLOOKUP(H8, AA:AA, AB:AB) * I8 -> 14700 | R8: =M8*0.0006 -> 23.82 | S8: =M8*0.02 -> 794 | T8: =L8-P8-Q8-R8-S8 -> 14182.18 | U8: =IF(K8="CORREO",0,N8) -> 10000 | V8: =T8*0.05 -> 709.109 | W8: =T8*0.05 -> 709.109 | AA8: Mini Recuerdo | AB8: 327 | AD8: 950 | AE8: =AD8-(AD8*0.1) -> 855
E9: Carina Manzano | H9: D6 Gold | I9: 55 | L9: 263340 | M9: 273340 | N9: =M9-L9 -> 10000 | P9: =_xlfn.XLOOKUP(H9, AA:AA, AB:AB) * I9 -> 131164 | R9: =M9*0.0006 -> 164.004 | S9: =M9*0.02 -> 5466.8 | T9: =L9-P9-Q9-R9-S9 -> 126545.2 | U9: =IF(K9="CORREO",0,N9) -> 10000 | V9: =T9*0.05 -> 6327.2598 | W9: =T9*0.05 -> 6327.2598 | AA9: Tarjeta | AB9: 330 | AD9: 980 | AE9: =AD9-(AD9*0.1) -> 882
L10: =IFERROR(IF(J10="Transferencia",_xlfn.XLOOKUP(H10,$AA:$AA,$AE:$AE)*I10,_xlfn.XLOOKUP(H10,$AA:$AA,$AD:$AD)*I10),0) -> 0 | N10: =M10-L10 -> 0 | P10: =_xlfn.XLOOKUP(H10, AA:AA, AB:AB) * I10 -> 0 | R10: =M10*0.0006 -> 0 | S10: =M10*0.02 -> 0 | T10: =L10-P10-Q10-R10-S10 -> 0 | U10: =IF(K10="CORREO",0,N10) -> 0 | V10: =T10*0.05 -> 0 | W10: =T10*0.05 -> 0 | AA10: Cajita de 4 | AB10: 1443.5 | AD10: 3000 | AE10: =AD10-(AD10*0.1) -> 2700
L11: =IFERROR(IF(J11="Transferencia",_xlfn.XLOOKUP(H11,$AA:$AA,$AE:$AE)*I11,_xlfn.XLOOKUP(H11,$AA:$AA,$AD:$AD)*I11),0) -> 0 | N11: =M11-L11 -> 0 | P11: =_xlfn.XLOOKUP(H11, AA:AA, AB:AB) * I11 -> 0 | R11: =M11*0.0006 -> 0 | S11: =M11*0.02 -> 0 | T11: =L11-P11-Q11-R11-S11 -> 0 | U11: =IF(K11="CORREO",0,N11) -> 0 | V11: =T11*0.05 -> 0 | W11: =T11*0.05 -> 0 | AA11: Cajita de 4 deluxe | AB11: 1499.86 | AD11: 3100 | AE11: =AD11-(AD11*0.1) -> 2790
L12: =IFERROR(IF(J12="Transferencia",_xlfn.XLOOKUP(H12,$AA:$AA,$AE:$AE)*I12,_xlfn.XLOOKUP(H12,$AA:$AA,$AD:$AD)*I12),0) -> 0 | N12: =M12-L12 -> 0 | P12: =_xlfn.XLOOKUP(H12, AA:AA, AB:AB) * I12 -> 0 | R12: =M12*0.0006 -> 0 | S12: =M12*0.02 -> 0 | T12: =L12-P12-Q12-R12-S12 -> 0 | U12: =IF(K12="CORREO",0,N12) -> 0 | V12: =T12*0.05 -> 0 | W12: =T12*0.05 -> 0 | AA12: D6 Classic | AB12: 2263.63 | AD12: 4900 | AE12: =AD12-(AD12*0.1) -> 4410
H13: Mini Recuerdo | I13: 100 | J13: Credito | K13: CORREO | L13: =IFERROR(IF(J13="Transferencia",_xlfn.XLOOKUP(H13,$AA:$AA,$AE:$AE)*I13,_xlfn.XLOOKUP(H13,$AA:$AA,$AD:$AD)*I13),0) -> 95000 | M13: 110000 | N13: =M13-L13 -> 15000 | P13: =_xlfn.XLOOKUP(H13, AA:AA, AB:AB) * I13 -> 32700 | R13: =L13*0.0006 -> 57 | S13: =L13*0.02 -> 1900 | T13: =L13-P13-Q13-R13-S13 -> 60343 | U13: =IF(K13="CORREO",0,N13) -> 0 | V13: =T13*0.05 -> 3017.15 | W13: =T13*0.05 -> 3017.15 | AA13: D6 Deluxe | AB13: 2422 | AD13: 5200 | AE13: =AD13-(AD13*0.1) -> 4680
J14: Transferencia | K14: CORREO | L14: =IFERROR(IF(J14="Transferencia",_xlfn.XLOOKUP(H14,$AA:$AA,$AE:$AE)*I14,_xlfn.XLOOKUP(H14,$AA:$AA,$AD:$AD)*I14),0) -> 0 | N14: =M14-L14 -> 0 | P14: =_xlfn.XLOOKUP(H14, AA:AA, AB:AB) * I14 -> 0 | R14: =M14*0.0006 -> 0 | S14: =M14*0.02 -> 0 | T14: =L14-P14-Q14-R14-S14 -> 0 | U14: =IF(K14="CORREO",0,N14) -> 0 | V14: =T14*0.05 -> 0 | W14: =T14*0.05 -> 0 | AA14: D6 Gold | AB14: 2384.8 | AD14: 5600 | AE14: =AD14-(AD14*0.1) -> 5040
L15: =IFERROR(IF(J15="Transferencia",_xlfn.XLOOKUP(H15,$AA:$AA,$AE:$AE)*I15,_xlfn.XLOOKUP(H15,$AA:$AA,$AD:$AD)*I15),0) -> 0 | N15: =M15-L15 -> 0 | P15: =_xlfn.XLOOKUP(H15, AA:AA, AB:AB) * I15 -> 0 | R15: =M15*0.0006 -> 0 | S15: =M15*0.02 -> 0 | T15: =L15-P15-Q15-R15-S15 -> 0 | U15: =IF(K15="CORREO",0,N15) -> 0 | V15: =T15*0.05 -> 0 | W15: =T15*0.05 -> 0 | AA15: Black | AB15: 2610 | AD15: 6100 | AE15: =AD15-(AD15*0.1) -> 5490
L16: =IFERROR(IF(J16="Transferencia",_xlfn.XLOOKUP(H16,$AA:$AA,$AE:$AE)*I16,_xlfn.XLOOKUP(H16,$AA:$AA,$AD:$AD)*I16),0) -> 0 | N16: =M16-L16 -> 0 | P16: =_xlfn.XLOOKUP(H16, AA:AA, AB:AB) * I16 -> 0 | R16: =M16*0.0006 -> 0 | S16: =M16*0.02 -> 0 | T16: =L16-P16-Q16-R16-S16 -> 0 | U16: =IF(K16="CORREO",0,N16) -> 0 | V16: =T16*0.05 -> 0 | W16: =T16*0.05 -> 0 | AA16: Señaladores | AB16: 440.7 | AD16: 1100 | AE16: =AD16-(AD16*0.1) -> 990
L17: =IFERROR(IF(J17="Transferencia",_xlfn.XLOOKUP(H17,$AA:$AA,$AE:$AE)*I17,_xlfn.XLOOKUP(H17,$AA:$AA,$AD:$AD)*I17),0) -> 0 | N17: =M17-L17 -> 0 | P17: =_xlfn.XLOOKUP(H17, AA:AA, AB:AB) * I17 -> 0 | R17: =M17*0.0006 -> 0 | S17: =M17*0.02 -> 0 | T17: =L17-P17-Q17-R17-S17 -> 0 | U17: =IF(K17="CORREO",0,N17) -> 0 | V17: =T17*0.05 -> 0 | W17: =T17*0.05 -> 0 | AA17: D2 | AB17: 1293 | AD17: 2850 | AE17: =AD17-(AD17*0.1) -> 2565
L18: =IFERROR(IF(J18="Transferencia",_xlfn.XLOOKUP(H18,$AA:$AA,$AE:$AE)*I18,_xlfn.XLOOKUP(H18,$AA:$AA,$AD:$AD)*I18),0) -> 0 | N18: =M18-L18 -> 0 | P18: =_xlfn.XLOOKUP(H18, AA:AA, AB:AB) * I18 -> 0 | R18: =M18*0.0006 -> 0 | S18: =M18*0.02 -> 0 | T18: =L18-P18-Q18-R18-S18 -> 0 | U18: =IF(K18="CORREO",0,N18) -> 0 | V18: =T18*0.05 -> 0 | W18: =T18*0.05 -> 0 | AA18: D2 moño | AB18: 1367 | AD18: 3500 | AE18: =AD18-(AD18*0.1) -> 3150
L19: =IFERROR(IF(J19="Transferencia",_xlfn.XLOOKUP(H19,$AA:$AA,$AE:$AE)*I19,_xlfn.XLOOKUP(H19,$AA:$AA,$AD:$AD)*I19),0) -> 0 | N19: =M19-L19 -> 0 | P19: =_xlfn.XLOOKUP(H19, AA:AA, AB:AB) * I19 -> 0 | R19: =M19*0.0006 -> 0 | S19: =M19*0.02 -> 0 | T19: =L19-P19-Q19-R19-S19 -> 0 | U19: =IF(K19="CORREO",0,N19) -> 0 | V19: =T19*0.05 -> 0 | W19: =T19*0.05 -> 0 | AA19: Vela 100cc | AD19: 2600 | AE19: =AD19-(AD19*0.1) -> 2340
L20: =IFERROR(IF(J20="Transferencia",_xlfn.XLOOKUP(H20,$AA:$AA,$AE:$AE)*I20,_xlfn.XLOOKUP(H20,$AA:$AA,$AD:$AD)*I20),0) -> 0 | N20: =M20-L20 -> 0 | P20: =_xlfn.XLOOKUP(H20, AA:AA, AB:AB) * I20 -> 0 | R20: =M20*0.0006 -> 0 | S20: =M20*0.02 -> 0 | T20: =L20-P20-Q20-R20-S20 -> 0 | U20: =IF(K20="CORREO",0,N20) -> 0 | V20: =T20*0.05 -> 0 | W20: =T20*0.05 -> 0 | AA20: Vela 200cc | AE20: =AD20-(AD20*0.1) -> 0
L21: =IFERROR(IF(J21="Transferencia",_xlfn.XLOOKUP(H21,$AA:$AA,$AE:$AE)*I21,_xlfn.XLOOKUP(H21,$AA:$AA,$AD:$AD)*I21),0) -> 0 | N21: =M21-L21 -> 0 | P21: =_xlfn.XLOOKUP(H21, AA:AA, AB:AB) * I21 -> 0 | R21: =M21*0.0006 -> 0 | S21: =M21*0.02 -> 0 | T21: =L21-P21-Q21-R21-S21 -> 0 | U21: =IF(K21="CORREO",0,N21) -> 0 | V21: =T21*0.05 -> 0 | W21: =T21*0.05 -> 0 | AA21: caja 44 chocos | AB21: 12512 | AD21: 31000 | AE21: =AD21-(AD21*0.1) -> 27900
L22: =IFERROR(IF(J22="Transferencia",_xlfn.XLOOKUP(H22,$AA:$AA,$AE:$AE)*I22,_xlfn.XLOOKUP(H22,$AA:$AA,$AD:$AD)*I22),0) -> 0 | N22: =M22-L22 -> 0 | P22: =_xlfn.XLOOKUP(H22, AA:AA, AB:AB) * I22 -> 0 | R22: =M22*0.0006 -> 0 | S22: =M22*0.02 -> 0 | T22: =L22-P22-Q22-R22-S22 -> 0 | U22: =IF(K22="CORREO",0,N22) -> 0 | V22: =T22*0.05 -> 0 | W22: =T22*0.05 -> 0 | AA22: Choco Suelto +200 | AB22: 294 | AD22: =AD6-(AD6*0.05) -> 627 | AE22: =AE6-(AE6*0.05) -> 564.3
L23: =IFERROR(IF(J23="Transferencia",_xlfn.XLOOKUP(H23,$AA:$AA,$AE:$AE)*I23,_xlfn.XLOOKUP(H23,$AA:$AA,$AD:$AD)*I23),0) -> 0 | N23: =M23-L23 -> 0 | P23: =_xlfn.XLOOKUP(H23, AA:AA, AB:AB) * I23 -> 0 | R23: =M23*0.0006 -> 0 | S23: =M23*0.02 -> 0 | T23: =L23-P23-Q23-R23-S23 -> 0 | U23: =IF(K23="CORREO",0,N23) -> 0 | V23: =T23*0.05 -> 0 | W23: =T23*0.05 -> 0
L24: =IFERROR(IF(J24="Transferencia",_xlfn.XLOOKUP(H24,$AA:$AA,$AE:$AE)*I24,_xlfn.XLOOKUP(H24,$AA:$AA,$AD:$AD)*I24),0) -> 0 | N24: =M24-L24 -> 0 | P24: =_xlfn.XLOOKUP(H24, AA:AA, AB:AB) * I24 -> 0 | R24: =M24*0.0006 -> 0 | S24: =M24*0.02 -> 0 | T24: =L24-P24-Q24-R24-S24 -> 0 | U24: =IF(K24="CORREO",0,N24) -> 0 | V24: =T24*0.05 -> 0 | W24: =T24*0.05 -> 0
L25: =IFERROR(IF(J25="Transferencia",_xlfn.XLOOKUP(H25,$AA:$AA,$AE:$AE)*I25,_xlfn.XLOOKUP(H25,$AA:$AA,$AD:$AD)*I25),0) -> 0 | N25: =M25-L25 -> 0 | P25: =_xlfn.XLOOKUP(H25, AA:AA, AB:AB) * I25 -> 0 | R25: =M25*0.0006 -> 0 | S25: =M25*0.02 -> 0 | T25: =L25-P25-Q25-R25-S25 -> 0 | U25: =IF(K25="CORREO",0,N25) -> 0 | V25: =T25*0.05 -> 0 | W25: =T25*0.05 -> 0
L26: =IFERROR(IF(J26="Transferencia",_xlfn.XLOOKUP(H26,$AA:$AA,$AE:$AE)*I26,_xlfn.XLOOKUP(H26,$AA:$AA,$AD:$AD)*I26),0) -> 0 | N26: =M26-L26 -> 0 | P26: =_xlfn.XLOOKUP(H26, AA:AA, AB:AB) * I26 -> 0 | R26: =M26*0.0006 -> 0 | S26: =M26*0.02 -> 0 | T26: =L26-P26-Q26-R26-S26 -> 0 | U26: =IF(K26="CORREO",0,N26) -> 0 | V26: =T26*0.05 -> 0 | W26: =T26*0.05 -> 0
L27: =IFERROR(IF(J27="Transferencia",_xlfn.XLOOKUP(H27,$AA:$AA,$AE:$AE)*I27,_xlfn.XLOOKUP(H27,$AA:$AA,$AD:$AD)*I27),0) -> 0 | N27: =M27-L27 -> 0 | P27: =_xlfn.XLOOKUP(H27, AA:AA, AB:AB) * I27 -> 0 | R27: =M27*0.0006 -> 0 | S27: =M27*0.02 -> 0 | T27: =L27-P27-Q27-R27-S27 -> 0 | U27: =IF(K27="CORREO",0,N27) -> 0 | V27: =T27*0.05 -> 0 | W27: =T27*0.05 -> 0
L28: =IFERROR(IF(J28="Transferencia",_xlfn.XLOOKUP(H28,$AA:$AA,$AE:$AE)*I28,_xlfn.XLOOKUP(H28,$AA:$AA,$AD:$AD)*I28),0) -> 0 | N28: =M28-L28 -> 0 | P28: =_xlfn.XLOOKUP(H28, AA:AA, AB:AB) * I28 -> 0 | R28: =M28*0.0006 -> 0 | S28: =M28*0.02 -> 0 | T28: =L28-P28-Q28-R28-S28 -> 0 | U28: =IF(K28="CORREO",0,N28) -> 0 | V28: =T28*0.05 -> 0 | W28: =T28*0.05 -> 0
L29: =IFERROR(IF(J29="Transferencia",_xlfn.XLOOKUP(H29,$AA:$AA,$AE:$AE)*I29,_xlfn.XLOOKUP(H29,$AA:$AA,$AD:$AD)*I29),0) -> 0 | N29: =M29-L29 -> 0 | P29: =_xlfn.XLOOKUP(H29, AA:AA, AB:AB) * I29 -> 0 | R29: =M29*0.0006 -> 0 | S29: =M29*0.02 -> 0 | T29: =L29-P29-Q29-R29-S29 -> 0 | U29: =IF(K29="CORREO",0,N29) -> 0 | V29: =T29*0.05 -> 0 | W29: =T29*0.05 -> 0
L30: =IFERROR(IF(J30="Transferencia",_xlfn.XLOOKUP(H30,$AA:$AA,$AE:$AE)*I30,_xlfn.XLOOKUP(H30,$AA:$AA,$AD:$AD)*I30),0) -> 0 | N30: =M30-L30 -> 0 | P30: =_xlfn.XLOOKUP(H30, AA:AA, AB:AB) * I30 -> 0 | R30: =M30*0.0006 -> 0 | S30: =M30*0.02 -> 0 | T30: =L30-P30-Q30-R30-S30 -> 0 | U30: =IF(K30="CORREO",0,N30) -> 0 | V30: =T30*0.05 -> 0 | W30: =T30*0.05 -> 0
L31: =IFERROR(IF(J31="Transferencia",_xlfn.XLOOKUP(H31,$AA:$AA,$AE:$AE)*I31,_xlfn.XLOOKUP(H31,$AA:$AA,$AD:$AD)*I31),0) -> 0 | N31: =M31-L31 -> 0 | P31: =_xlfn.XLOOKUP(H31, AA:AA, AB:AB) * I31 -> 0 | R31: =M31*0.0006 -> 0 | S31: =M31*0.02 -> 0 | T31: =L31-P31-Q31-R31-S31 -> 0 | U31: =IF(K31="CORREO",0,N31) -> 0 | V31: =T31*0.05 -> 0 | W31: =T31*0.05 -> 0
L32: =IFERROR(IF(J32="Transferencia",_xlfn.XLOOKUP(H32,$AA:$AA,$AE:$AE)*I32,_xlfn.XLOOKUP(H32,$AA:$AA,$AD:$AD)*I32),0) -> 0 | N32: =M32-L32 -> 0 | P32: =_xlfn.XLOOKUP(H32, AA:AA, AB:AB) * I32 -> 0 | R32: =M32*0.0006 -> 0 | S32: =M32*0.02 -> 0 | T32: =L32-P32-Q32-R32-S32 -> 0 | U32: =IF(K32="CORREO",0,N32) -> 0 | V32: =T32*0.05 -> 0 | W32: =T32*0.05 -> 0
L33: =IFERROR(IF(J33="Transferencia",_xlfn.XLOOKUP(H33,$AA:$AA,$AE:$AE)*I33,_xlfn.XLOOKUP(H33,$AA:$AA,$AD:$AD)*I33),0) -> 0 | N33: =M33-L33 -> 0 | P33: =_xlfn.XLOOKUP(H33, AA:AA, AB:AB) * I33 -> 0 | R33: =M33*0.0006 -> 0 | S33: =M33*0.02 -> 0 | T33: =L33-P33-Q33-R33-S33 -> 0 | U33: =IF(K33="CORREO",0,N33) -> 0 | V33: =T33*0.05 -> 0 | W33: =T33*0.05 -> 0
L34: =IFERROR(IF(J34="Transferencia",_xlfn.XLOOKUP(H34,$AA:$AA,$AE:$AE)*I34,_xlfn.XLOOKUP(H34,$AA:$AA,$AD:$AD)*I34),0) -> 0 | N34: =M34-L34 -> 0 | P34: =_xlfn.XLOOKUP(H34, AA:AA, AB:AB) * I34 -> 0 | R34: =M34*0.0006 -> 0 | S34: =M34*0.02 -> 0 | T34: =L34-P34-Q34-R34-S34 -> 0 | U34: =IF(K34="CORREO",0,N34) -> 0 | V34: =T34*0.05 -> 0 | W34: =T34*0.05 -> 0
C35: MELI | L35: =IFERROR(IF(J35="Transferencia",_xlfn.XLOOKUP(H35,$AA:$AA,$AE:$AE)*I35,_xlfn.XLOOKUP(H35,$AA:$AA,$AD:$AD)*I35),0) -> 0 | N35: =M35-L35 -> 0 | P35: =_xlfn.XLOOKUP(H35, AA:AA, AB:AB) * I35 -> 0 | R35: =M35*0.0006 -> 0 | S35: =M35*0.02 -> 0 | T35: =L35-P35-Q35-R35-S35 -> 0 | U35: =IF(K35="CORREO",0,N35) -> 0 | V35: =T35*0.05 -> 0 | W35: =T35*0.05 -> 0
C36: MELI | L36: =IFERROR(IF(J36="Transferencia",_xlfn.XLOOKUP(H36,$AA:$AA,$AE:$AE)*I36,_xlfn.XLOOKUP(H36,$AA:$AA,$AD:$AD)*I36),0) -> 0 | N36: =M36-L36 -> 0 | P36: =_xlfn.XLOOKUP(H36, AA:AA, AB:AB) * I36 -> 0 | R36: =M36*0.0006 -> 0 | S36: =M36*0.02 -> 0 | T36: =L36-P36-Q36-R36-S36 -> 0 | U36: =IF(K36="CORREO",0,N36) -> 0 | V36: =T36*0.05 -> 0 | W36: =T36*0.05 -> 0
C37: MELI | L37: =IFERROR(IF(J37="Transferencia",_xlfn.XLOOKUP(H37,$AA:$AA,$AE:$AE)*I37,_xlfn.XLOOKUP(H37,$AA:$AA,$AD:$AD)*I37),0) -> 0 | N37: =M37-L37 -> 0 | P37: =_xlfn.XLOOKUP(H37, AA:AA, AB:AB) * I37 -> 0 | R37: =M37*0.0006 -> 0 | S37: =M37*0.02 -> 0 | T37: =L37-P37-Q37-R37-S37 -> 0 | U37: =IF(K37="CORREO",0,N37) -> 0 | V37: =T37*0.05 -> 0 | W37: =T37*0.05 -> 0
C38: MELI | L38: =IFERROR(IF(J38="Transferencia",_xlfn.XLOOKUP(H38,$AA:$AA,$AE:$AE)*I38,_xlfn.XLOOKUP(H38,$AA:$AA,$AD:$AD)*I38),0) -> 0 | N38: =M38-L38 -> 0 | P38: =_xlfn.XLOOKUP(H38, AA:AA, AB:AB) * I38 -> 0 | R38: =M38*0.0006 -> 0 | S38: =M38*0.02 -> 0 | T38: =L38-P38-Q38-R38-S38 -> 0 | U38: =IF(K38="CORREO",0,N38) -> 0 | V38: =T38*0.05 -> 0 | W38: =T38*0.05 -> 0
C39: MELI | L39: =IFERROR(IF(J39="Transferencia",_xlfn.XLOOKUP(H39,$AA:$AA,$AE:$AE)*I39,_xlfn.XLOOKUP(H39,$AA:$AA,$AD:$AD)*I39),0) -> 0 | N39: =M39-L39 -> 0 | P39: =_xlfn.XLOOKUP(H39, AA:AA, AB:AB) * I39 -> 0 | R39: =M39*0.0006 -> 0 | S39: =M39*0.02 -> 0 | T39: =L39-P39-Q39-R39-S39 -> 0 | U39: =IF(K39="CORREO",0,N39) -> 0 | V39: =T39*0.05 -> 0 | W39: =T39*0.05 -> 0
C40: MELI | L40: =IFERROR(IF(J40="Transferencia",_xlfn.XLOOKUP(H40,$AA:$AA,$AE:$AE)*I40,_xlfn.XLOOKUP(H40,$AA:$AA,$AD:$AD)*I40),0) -> 0 | N40: =M40-L40 -> 0 | P40: =_xlfn.XLOOKUP(H40, AA:AA, AB:AB) * I40 -> 0 | R40: =M40*0.0006 -> 0 | S40: =M40*0.02 -> 0 | T40: =L40-P40-Q40-R40-S40 -> 0 | U40: =IF(K40="CORREO",0,N40) -> 0 | V40: =T40*0.05 -> 0 | W40: =T40*0.05 -> 0
...

Sheet Ventas MELI
T1: 0.15
A2: ESTADO | B2: Fecha | C2: Nombre AD | E2: Telefono | F2: Producto | G2: Cantidad | H2: FACTURÓ | I2: Cargo por venta | J2: Costo fijo | K2: "impuestos" P | L2: Envio entró | M2: Envio salio | N2: Envio Flex | P2: me quedó | Q2: Costo | R2: Ganancia | S2: MONOTRIBUTO | T2: 0.02 | X2: Chocos Colonial Usados | Z2: NECESITO
C3: Diciembre | T3: Brisa | U3: =SUM(T4:T39) -> 11017.869 | V3: FLEX
V4: =SUM(T3:T32) -> 9433.1812 | W4: Facturacion | X4: Me quedó | Y4: Costos | Z4: Ganancias | AE4: Choco Suelto | AF4: 294
C5: Maria Belen Argañaras | F5: Cajita de 4 | G5: 10 | H5: 41800 | I5: -5684.8 | J5: -4600 | K5: -627 | L5: 10245.99 | M5: 0 | N5: =IF(O5="Mercado Envíos Flex","SI","NO") -> SI | O5: Mercado Envíos Flex | P5: =H5+I5+J5+K5+L5+M5 -> 41134.19 | Q5: =_xlfn.XLOOKUP(F5, AE:AE, AF:AF) * G5 -> 14435 | R5: =IF(N5="Si", P5-Q5-L5, P5-Q5) -> 16453.2 | S5: =R5*0.05 -> 822.66 | T5: =R5*$T$2 -> 329.064 | V5: =IF(N5= "Si",L5,0) -> 10245.99 | W5: =SUM(H5:H400) -> 1294600 | X5: =SUM(P5:P400) -> 1030724 | Y5: =SUM(Q5:Q400) -> 411776.5 | Z5: =SUM(R5:R400) -> 550893.46 | AE5: Mini Recuerdo | AF5: 327
C6: Joana Fernandez Castro | F6: Choco Suelto | G6: 75 | H6: 67500 | I6: -9180 | J6: -6900 | K6: 0 | L6: 7370.99 | M6: 0 | N6: =IF(O6="Mercado Envíos Flex","SI","NO") -> SI | O6: Mercado Envíos Flex | P6: =H6+I6+J6+K6+L6+M6 -> 58790.99 | Q6: =_xlfn.XLOOKUP(F6, AE:AE, AF:AF) * G6 -> 22050 | R6: =IF(N6="Si", P6-Q6-L6, P6-Q6) -> 29370 | S6: =R6*0.05 -> 1468.5 | T6: =R6*$T$2 -> 587.4 | V6: =IF(N6= "Si",L6,0) -> 7370.99 | AE6: Tarjeta | AF6: 330
C7: Ximena Anahi Barraza | F7: Cajita de 4 | G7: 5 | H7: 20900 | I7: -2842.4 | J7: -2300 | K7: -313.5 | L7: 16830.99 | M7: -16830.99 | N7: =IF(O7="Mercado Envíos Flex","SI","NO") -> NO | O7: Correo y puntos de despacho | P7: =H7+I7+J7+K7+L7+M7 -> 15444.1 | Q7: =_xlfn.XLOOKUP(F7, AE:AE, AF:AF) * G7 -> 7217.5 | R7: =IF(N7="Si", P7-Q7-L7, P7-Q7) -> 8226.6 | S7: =R7*0.05 -> 411.33 | T7: =R7*$T$2 -> 164.532 | V7: =IF(N7= "Si",L7,0) -> 0 | AE7: Cajita de 4 | AF7: 1443.5
C8: Liana Roxana Castello | F8: Choco Suelto | G8: 25 | H8: 22500 | I8: -3060 | J8: -2300 | K8: 0 | L8: 7370.99 | M8: 0 | N8: =IF(O8="Mercado Envíos Flex","SI","NO") -> SI | O8: Mercado Envíos Flex | P8: =H8+I8+J8+K8+L8+M8 -> 24510.99 | Q8: =_xlfn.XLOOKUP(F8, AE:AE, AF:AF) * G8 -> 7350 | R8: =IF(N8="Si", P8-Q8-L8, P8-Q8) -> 9790 | S8: =R8*0.05 -> 489.5 | T8: =R8*$T$2 -> 195.8 | V8: =IF(N8= "Si",L8,0) -> 7370.99 | AE8: Cajita de 4 deluxe | AF8: 1499.86
C9: Sebastian Martinez Boichuk | F9: Choco Suelto | G9: 25 | H9: 22500 | I9: -3060 | J9: -2300 | K9: 0 | L9: 7370.99 | M9: 0 | N9: =IF(O9="Mercado Envíos Flex","SI","NO") -> SI | O9: Mercado Envíos Flex | P9: =H9+I9+J9+K9+L9+M9 -> 24510.99 | Q9: =_xlfn.XLOOKUP(F9, AE:AE, AF:AF) * G9 -> 7350 | R9: =IF(N9="Si", P9-Q9-L9, P9-Q9) -> 9790 | S9: =R9*0.05 -> 489.5 | T9: =R9*$T$2 -> 195.8 | V9: =IF(N9= "Si",L9,0) -> 7370.99 | AE9: D6 Classic | AF9: 2263.63
C10: Miryam Edith Zavaley | F10: Choco Suelto | G10: 25 | H10: 22500 | I10: -3060 | J10: -2300 | K10: -475.28 | L10: 9185.14 | M10: -9185.14 | N10: =IF(O10="Mercado Envíos Flex","SI","NO") -> NO | O10: Correo y puntos de despacho | P10: =H10+I10+J10+K10+L10+M10 -> 16664.72 | Q10: =_xlfn.XLOOKUP(F10, AE:AE, AF:AF) * G10 -> 7350 | R10: =IF(N10="Si", P10-Q10-L10, P10-Q10) -> 9314.72 | S10: =R10*0.05 -> 465.736 | T10: =R10*$T$2 -> 186.2944 | V10: =IF(N10= "Si",L10,0) -> 0 | AE10: D6 Deluxe | AF10: 2422
C11: Marina Gisela di Fonzo | F11: Choco Suelto | G11: 50 | H11: 51000 | I11: -6936 | J11: -5620 | K11: -765 | L11: 0 | M11: 0 | N11: =IF(O11="Mercado Envíos Flex","SI","NO") -> NO | O11: Correo y puntos de despacho | P11: =H11+I11+J11+K11+L11+M11 -> 37679 | Q11: =_xlfn.XLOOKUP(F11, AE:AE, AF:AF) * G11 -> 14700 | R11: =IF(N11="Si", P11-Q11-L11, P11-Q11) -> 22979 | S11: =R11*0.05 -> 1148.95 | T11: =R11*$T$2 -> 459.58 | V11: =IF(N11= "Si",L11,0) -> 0 | AE11: D6 Gold | AF11: 2384.8
C12: Daniela Anahi Ramallo | F12: Choco Suelto | G12: 25 | H12: 22500 | I12: -3060 | J12: -2300 | K12: -426.58 | L12: 5938.79 | M12: -5938.79 | N12: =IF(O12="Mercado Envíos Flex","SI","NO") -> NO | O12: Correo y puntos de despacho | P12: =H12+I12+J12+K12+L12+M12 -> 16713.42 | Q12: =_xlfn.XLOOKUP(F12, AE:AE, AF:AF) * G12 -> 7350 | R12: =IF(N12="Si", P12-Q12-L12, P12-Q12) -> 9363.42 | S12: =R12*0.05 -> 468.171 | T12: =R12*$T$2 -> 187.2684 | V12: =IF(N12= "Si",L12,0) -> 0 | AE12: Black | AF12: 2610
C13: Veronica Andrea Surdo | F13: Mini Recuerdo | G13: 25 | H13: 36000 | I13: -5220 | J13: 0 | K13: -540 | L13: 461.1 | M13: 0 | N13: =IF(O13="Mercado Envíos Flex","SI","NO") -> SI | O13: Mercado Envíos Flex | P13: =H13+I13+J13+K13+L13+M13 -> 30701.1 | Q13: =_xlfn.XLOOKUP(F13, AE:AE, AF:AF) * G13 -> 8175 | R13: =IF(N13="Si", P13-Q13-L13, P13-Q13) -> 22065 | S13: =R13*0.05 -> 1103.25 | T13: =R13*$T$2 -> 441.3 | V13: =IF(N13= "Si",L13,0) -> 461.1 | AE13: Señaladores | AF13: 440.7
C14: Mabel Susana Gazzero | F14: Choco Suelto | G14: 25 | H14: 22500 | I14: -3060 | J14: -2300 | K14: -337.5 | L14: 5942.79 | M14: -5942.79 | N14: =IF(O14="Mercado Envíos Flex","SI","NO") -> NO | O14: Correo y puntos de despacho | P14: =H14+I14+J14+K14+L14+M14 -> 16802.5 | Q14: =_xlfn.XLOOKUP(F14, AE:AE, AF:AF) * G14 -> 7350 | R14: =IF(N14="Si", P14-Q14-L14, P14-Q14) -> 9452.5 | S14: =R14*0.05 -> 472.625 | T14: =R14*$T$2 -> 189.05 | V14: =IF(N14= "Si",L14,0) -> 0 | AE14: D2 | AF14: 1293
C15: Horacio Atilio Ribero | F15: Caja 44 Chocos | G15: 1 | H15: 32900 | I15: -4474.4 | J15: -2810 | K15: -558.24 | L15: 4315.94 | M15: -4315.94 | N15: =IF(O15="Mercado Envíos Flex","SI","NO") -> NO | O15: Correo y puntos de despacho | P15: =H15+I15+J15+K15+L15+M15 -> 25057.36 | Q15: =_xlfn.XLOOKUP(F15, AE:AE, AF:AF) * G15 -> 12512 | R15: =IF(N15="Si", P15-Q15-L15, P15-Q15) -> 12545.36 | S15: =R15*0.05 -> 627.268 | T15: =R15*$T$2 -> 250.9072 | V15: =IF(N15= "Si",L15,0) -> 0 | AE15: D2 moño | AF15: 1367
C16: Andrea Natalia Castro | F16: Mini Recuerdo | G16: 25 | H16: 36000 | I16: -5220 | J16: 0 | K16: -540 | L16: 0 | M16: -6560.49 | N16: =IF(O16="Mercado Envíos Flex","SI","NO") -> NO | O16: Correo y puntos de despacho | P16: =H16+I16+J16+K16+L16+M16 -> 23679.51 | Q16: =_xlfn.XLOOKUP(F16, AE:AE, AF:AF) * G16 -> 8175 | R16: =IF(N16="Si", P16-Q16-L16, P16-Q16) -> 15504.51 | S16: =R16*0.05 -> 775.2255 | T16: =R16*$T$2 -> 310.0902 | V16: =IF(N16= "Si",L16,0) -> 0 | AE16: Vela 100cc
C17: Teresa Silvina Petracca | F17: Choco Suelto | G17: 25 | H17: 22500 | I17: -3060 | J17: -2300 | K17: -437.86 | L17: 6690.99 | M17: -6690.99 | N17: =IF(O17="Mercado Envíos Flex","SI","NO") -> NO | O17: Correo y puntos de despacho | P17: =H17+I17+J17+K17+L17+M17 -> 16702.14 | Q17: =_xlfn.XLOOKUP(F17, AE:AE, AF:AF) * G17 -> 7350 | R17: =IF(N17="Si", P17-Q17-L17, P17-Q17) -> 9352.14 | S17: =R17*0.05 -> 467.607 | T17: =R17*$T$2 -> 187.0428 | V17: =IF(N17= "Si",L17,0) -> 0 | AE17: Vela 200cc
C18: Cristina Mabel Salatin | F18: Choco Suelto | G18: 25 | H18: 22500 | I18: -3060 | J18: -2300 | K18: -426.58 | L18: 5938.79 | M18: -5938.79 | N18: =IF(O18="Mercado Envíos Flex","SI","NO") -> NO | O18: Correo y puntos de despacho | P18: =H18+I18+J18+K18+L18+M18 -> 16713.42 | Q18: =_xlfn.XLOOKUP(F18, AE:AE, AF:AF) * G18 -> 7350 | R18: =IF(N18="Si", P18-Q18-L18, P18-Q18) -> 9363.42 | S18: =R18*0.05 -> 468.171 | T18: =R18*$T$2 -> 187.2684 | V18: =IF(N18= "Si",L18,0) -> 0 | AE18: caja 44 chocos | AF18: 12512
C19: Liana Roxana Castello | F19: Choco Suelto | G19: 25 | H19: 22500 | I19: -3060 | J19: -2300 | K19: 0 | L19: 7370.99 | M19: 0 | N19: =IF(O19="Mercado Envíos Flex","SI","NO") -> SI | O19: Mercado Envíos Flex | P19: =H19+I19+J19+K19+L19+M19 -> 24510.99 | Q19: =_xlfn.XLOOKUP(F19, AE:AE, AF:AF) * G19 -> 7350 | R19: =IF(N19="Si", P19-Q19-L19, P19-Q19) -> 9790 | S19: =R19*0.05 -> 489.5 | T19: =R19*$T$2 -> 195.8 | V19: =IF(N19= "Si",L19,0) -> 7370.99
C20: Ximena Alejandra Cisneros | F20: Choco Suelto | G20: 400 | H20: 316000 | I20: -42976 | J20: 0 | K20: -4740 | L20: 0 | M20: -28001.98 | N20: =IF(O20="Mercado Envíos Flex","SI","NO") -> NO | O20: Correo y puntos de despacho | P20: =H20+I20+J20+K20+L20+M20 -> 240282.02 | Q20: =_xlfn.XLOOKUP(F20, AE:AE, AF:AF) * G20 -> 117600 | R20: =IF(N20="Si", P20-Q20-L20, P20-Q20) -> 122682.02 | S20: =R20*0.05 -> 6134.101 | T20: =R20*$T$2 -> 2453.6404 | V20: =IF(N20= "Si",L20,0) -> 0
C21: Martin Leonardo Cardenas | F21: Choco Suelto | G21: 50 | H21: 45000 | I21: -6120 | J21: -4600 | K21: -675 | L21: 10245.99 | M21: 0 | N21: =IF(O21="Mercado Envíos Flex","SI","NO") -> SI | O21: Mercado Envíos Flex | P21: =H21+I21+J21+K21+L21+M21 -> 43850.99 | Q21: =_xlfn.XLOOKUP(F21, AE:AE, AF:AF) * G21 -> 14700 | R21: =IF(N21="Si", P21-Q21-L21, P21-Q21) -> 18905 | S21: =R21*0.05 -> 945.25 | T21: =R21*$T$2 -> 378.1 | V21: =IF(N21= "Si",L21,0) -> 10245.99
C22: Silvana Veronica Castagnari | F22: Mini Recuerdo | G22: 25 | H22: 36000 | I22: -5220 | J22: 0 | K22: -540 | L22: 0 | M22: -6560.49 | N22: =IF(O22="Mercado Envíos Flex","SI","NO") -> NO | O22: Correo y puntos de despacho | P22: =H22+I22+J22+K22+L22+M22 -> 23679.51 | Q22: =_xlfn.XLOOKUP(F22, AE:AE, AF:AF) * G22 -> 8175 | R22: =IF(N22="Si", P22-Q22-L22, P22-Q22) -> 15504.51 | S22: =R22*0.05 -> 775.2255 | T22: =R22*$T$2 -> 310.0902 | V22: =IF(N22= "Si",L22,0) -> 0
C23: Carolina Elizabeth Baez | F23: Mini Recuerdo | G23: 25 | H23: 36000 | I23: -5220 | J23: 0 | K23: -540 | L23: 0 | M23: -6560.49 | N23: =IF(O23="Mercado Envíos Flex","SI","NO") -> NO | O23: Correo y puntos de despacho | P23: =H23+I23+J23+K23+L23+M23 -> 23679.51 | Q23: =_xlfn.XLOOKUP(F23, AE:AE, AF:AF) * G23 -> 8175 | R23: =IF(N23="Si", P23-Q23-L23, P23-Q23) -> 15504.51 | S23: =R23*0.05 -> 775.2255 | T23: =R23*$T$2 -> 310.0902 | V23: =IF(N23= "Si",L23,0) -> 0
C24: Marina Vanesa Barbieri | F24: Choco Suelto | G24: 25 | H24: 22500 | I24: -3060 | J24: -2300 | K24: -437.86 | L24: 6690.99 | M24: -6690.99 | N24: =IF(O24="Mercado Envíos Flex","SI","NO") -> NO | O24: Correo y puntos de despacho | P24: =H24+I24+J24+K24+L24+M24 -> 16702.14 | Q24: =_xlfn.XLOOKUP(F24, AE:AE, AF:AF) * G24 -> 7350 | R24: =IF(N24="Si", P24-Q24-L24, P24-Q24) -> 9352.14 | S24: =R24*0.05 -> 467.607 | T24: =R24*$T$2 -> 187.0428 | V24: =IF(N24= "Si",L24,0) -> 0
C25: Patricia Analia Penna | F25: Choco Suelto | G25: 50 | H25: 45000 | I25: -6120 | J25: -4600 | K25: -675 | L25: 0 | M25: 0 | N25: =IF(O25="Mercado Envíos Flex","SI","NO") -> NO | O25: Correo y puntos de despacho | P25: =H25+I25+J25+K25+L25+M25 -> 33605 | Q25: =_xlfn.XLOOKUP(F25, AE:AE, AF:AF) * G25 -> 14700 | R25: =IF(N25="Si", P25-Q25-L25, P25-Q25) -> 18905 | S25: =R25*0.05 -> 945.25 | T25: =R25*$T$2 -> 378.1 | V25: =IF(N25= "Si",L25,0) -> 0
R26: =IF(N26="Si", P26-Q26-L26, P26-Q26) -> 0 | S26: =R26*0.05 -> 0 | T26: =R26*$T$2 -> 0 | V26: =IF(N26= "Si",L26,0) -> 0
A27: 29 | C27: cristian kilapi | F27: Mini Recuerdo | G27: 25 | H27: 36000 | I27: -5220 | J27: 0 | K27: -540 | L27: 4075.49 | M27: -10635.98 | N27: =IF(O27="Mercado Envíos Flex","SI","NO") -> NO | O27: Correo y puntos de despacho | P27: =H27+I27+J27+K27+L27+M27 -> 23679.51 | Q27: =_xlfn.XLOOKUP(F27, AE:AE, AF:AF) * G27 -> 8175 | R27: =IF(N27="Si", P27-Q27-L27, P27-Q27) -> 15504.51 | S27: =R27*0.05 -> 775.2255 | T27: =R27*$T$2 -> 310.0902 | V27: =IF(N27= "Si",L27,0) -> 0
A28: 30 | C28: EDIT NORA MAITINI | F28: Choco Suelto | G28: 25 | H28: 22500 | I28: -3060 | J28: -2300 | K28: 0 | L28: 7370.99 | M28: 0 | N28: =IF(O28="Mercado Envíos Flex","SI","NO") -> SI | O28: Mercado Envíos Flex | P28: =H28+I28+J28+K28+L28+M28 -> 24510.99 | Q28: =_xlfn.XLOOKUP(F28, AE:AE, AF:AF) * G28 -> 7350 | R28: =IF(N28="Si", P28-Q28-L28, P28-Q28) -> 9790 | S28: =R28*0.05 -> 489.5 | T28: =R28*$T$2 -> 195.8 | V28: =IF(N28= "Si",L28,0) -> 7370.99
A29: 31 | C29: Diana Inchauspe | F29: Choco Suelto | G29: 50 | H29: 55400 | I29: -7830.5 | J29: -5110 | K29: -831 | L29: 0 | M29: 0 | N29: =IF(O29="Mercado Envíos Flex","SI","NO") -> NO | O29: Correo y puntos de despacho | P29: =H29+I29+J29+K29+L29+M29 -> 41628.5 | Q29: =_xlfn.XLOOKUP(F29, AE:AE, AF:AF) * G29 -> 14700 | R29: =IF(N29="Si", P29-Q29-L29, P29-Q29) -> 26928.5 | S29: =R29*0.05 -> 1346.425 | T29: =R29*$T$2 -> 538.57 | V29: =IF(N29= "Si",L29,0) -> 0
N30: =IF(O30="Mercado Envíos Flex","SI","NO") -> NO | T30: =R30*$T$2 -> 0
N31: =IF(O31="Mercado Envíos Flex","SI","NO") -> NO | T31: =R31*$T$2 -> 0
A32: 34 | C32: Silvana Robel | F32: Mini Recuerdo | G32: 25 | H32: 31200 | I32: -4524 | J32: -2810 | K32: -468 | L32: 9155.99 | M32: -9155.99 | N32: =IF(O32="Mercado Envíos Flex","SI","NO") -> NO | O32: Correo y puntos de despacho | P32: =H32+I32+J32+K32+L32+M32 -> 23398 | Q32: =_xlfn.XLOOKUP(F32, AE:AE, AF:AF) * G32 -> 8175 | R32: =IF(N32="Si", P32-Q32-L32, P32-Q32) -> 15223 | S32: =R32*0.05 -> 761.15 | T32: =R32*$T$2 -> 304.46 | V32: =IF(N32= "Si",L32,0) -> 0
C33: María ines Monzo | F33: Choco Suelto | G33: 25 | H33: 25000 | I33: -3400 | J33: -2810 | K33: -450.96 | L33: 5064.14 | M33: -5064.14 | N33: =IF(O33="Mercado Envíos Flex","SI","NO") -> NO | O33: Correo y puntos de despacho | P33: 18339.04 | Q33: =_xlfn.XLOOKUP(F33, AE:AE, AF:AF) * G33 -> 7350 | R33: =IF(N33="Si", P33-Q33-L33, P33-Q33) -> 10989.04 | S33: =R33*0.05 -> 549.452 | T33: =R33*$T$2 -> 219.7808
C34: Lisi cas | F34: Choco Suelto | G34: 100 | H34: 100000 | I34: -13600 | J34: -11240 | K34: -1500 | L34: 10245.99 | M34: 0 | N34: =IF(O34="Mercado Envíos Flex","SI","NO") -> SI | O34: Mercado Envíos Flex | P34: 83905.99 | Q34: =_xlfn.XLOOKUP(F34, AE:AE, AF:AF) * G34 -> 29400 | R34: =IF(N34="Si", P34-Q34-L34, P34-Q34) -> 44260 | S34: =R34*0.05 -> 2213 | T34: =R34*$T$2 -> 885.2
C35: Myriam | F35: Choco Suelto | G35: 25 | H35: 25000 | I35: -3400 | J35: -2810 | L35: 4667.64 | M35: -4667.64 | N35: =IF(O35="Mercado Envíos Flex","SI","NO") -> NO | O35: Correo y puntos de despacho | P35: 18790 | Q35: =_xlfn.XLOOKUP(F35, AE:AE, AF:AF) * G35 -> 7350 | R35: =IF(N35="Si", P35-Q35-L35, P35-Q35) -> 11440 | S35: =R35*0.05 -> 572 | T35: =R35*$T$2 -> 228.8 | V35: =IF(N35= "Si",L35,0) -> 0
C36: Horacio Ribero | F36: Caja 44 Chocos | G36: 1 | H36: 32900 | I36: -4474.4 | J36: -2810 | K36: -558.24 | L36: 4315.94 | M36: -4315.94 | N36: =IF(O36="Mercado Envíos Flex","SI","NO") -> NO | O36: Correo y puntos de despacho | P36: 25057.36 | Q36: =_xlfn.XLOOKUP(F36, AE:AE, AF:AF) * G36 -> 12512 | R36: =IF(N36="Si", P36-Q36-L36, P36-Q36) -> 12545.36 | S36: =R36*0.05 -> 627.268 | T36: =R36*$T$2 -> 250.9072 | V36: =IF(N36= "Si",L36,0) -> 0
N37: =IF(O37="Mercado Envíos Flex","SI","NO") -> NO | Q37: =_xlfn.XLOOKUP(F37, AE:AE, AF:AF) * G37 -> 0 | R37: =IF(N37="Si", P37-Q37-L37, P37-Q37) -> 0 | S37: =R37*0.05 -> 0 | T37: =R37*$T$2 -> 0
N38: =IF(O38="Mercado Envíos Flex","SI","NO") -> NO | Q38: =_xlfn.XLOOKUP(F38, AE:AE, AF:AF) * G38 -> 0 | R38: =IF(N38="Si", P38-Q38-L38, P38-Q38) -> 0 | S38: =R38*0.05 -> 0 | T38: =R38*$T$2 -> 0
N39: =IF(O39="Mercado Envíos Flex","SI","NO") -> NO | Q39: =_xlfn.XLOOKUP(F39, AE:AE, AF:AF) * G39 -> 0 | R39: =IF(N39="Si", P39-Q39-L39, P39-Q39) -> 0 | S39: =R39*0.05 -> 0 | T39: =R39*$T$2 -> 0
N40: =IF(O40="Mercado Envíos Flex","SI","NO") -> NO | Q40: =_xlfn.XLOOKUP(F40, AE:AE, AF:AF) * G40 -> 0 | R40: =IF(N40="Si", P40-Q40-L40, P40-Q40) -> 0 | S40: =R40*0.05 -> 0 | T40: =R40*$T$2 -> 0
...

Sheet Coloniales S.C
Q1: Descontar
O2: Aumento | Q2: 0.0925
O3: 0.1
O4: 0.1 | Q4: 0.0761 | R4: =O7*Q4 -> 60.119
O5: =O3+O4 -> 0.2 | Q5: =Q3+Q4+Q2 -> 0.1686 | T5: Descuento | U5: Descuento | V5: Descuento
B6: Choco suelto simple o full color | C6: Choco | D6: Etiqueta choco | K6: Costo | L6: Ganancia | M6: Total | O6: MP | P6: MP | Q6: Ganan MP | T6: 0 | U6: 0 | V6: 0.05
C7: =Insumos!C6 -> 224 | D7: =Insumos!$G$6/28 -> 8.5685714 | F7: 40 | K7: =C7+D7 -> 232.56857 | L7: =M7-K7 -> 418.62343 | M7: =K7*2.8 -> 651.192 | O7: =ROUNDUP(P7, -1) -> 790 | P7: =M7+(M7*O5) -> 781.4304 | Q7: =O7-(O7*Q5)-K7 -> 424.23743 | T7: 50 | U7: 100 | V7: 200
T8: Costo total
B9: 2000 | C9: =Insumos!D12 -> 205.838 | D9: =Insumos!$G$6/28 -> 8.5685714 | K9: =C9+D9 -> 214.40657 | M9: =$L$7+K9 -> 633.03 | T9: =$K$7*T7 -> 11628.429 | U9: =$K$7*U7 -> 23256.857 | V9: =$K$7*V7 -> 46513.714
T10: Mercado Pago
O11: descuento | Q11: IIBB | T11: =($O7*T7)-(($O7*T7)*T6) -> 39500 | U11: =($O7*U7)-(($O7*U7)*U6) -> 79000 | V11: =($O7*V7)-(($O7*V7)*V6) -> 150100
O12: 0.1 | Q12: 0.06 | T12: =T11/T7 -> 790 | U12: =U11/U7 -> 790 | V12: =V11/V7 -> 750.5
O13: Transf | Q13: G. Transf | T13: Ganancia MP
O14: =O7-(O7*O12) -> 711 | Q14: =(O14-(O14*Q12))-#REF! -> #REF! | T14: =(T11-T9)-(T11*$Q$5) -> 21211.871 | U14: =(U11-U9)-(U11*$Q$5) -> 42423.743 | V14: =(V11-V9)-(V11*$Q$5) -> 78279.426
T15: =T14/T7 -> 424.23743 | U15: =U14/U7 -> 424.23743 | V15: =V14/V7 -> 391.39713
T16: Transferencia
T17: =T11-(T11*T18) -> 35550 | U17: =U11-(U11*U18) -> 71100 | V17: =V11-(V11*V18) -> 135090
T18: =$O$12 -> 0.1 | U18: =$O$12 -> 0.1 | V18: =$O$12 -> 0.1
T19: =T17/T7 -> 711 | U19: =U17/U7 -> 711 | V19: =V17/V7 -> 675.45
T20: Ganancia transferencia
T21: =T17-(T17*$Q$12)-T9 -> 21788.571 | U21: =U17-(U17*$Q$117)-U9 -> 42432.433 | V21: =V17-(V17*$Q$117)-V9 -> 78295.937
T22: =T21/T7 -> 435.77143 | U22: =U21/U7 -> 424.32433 | V22: =V21/V7 -> 391.47968
Q24: Descontar
O25: Aumento | Q25: 0.0925
O26: 0.1
C27: Coloniales | O27: 0.1 | Q27: 0.0761 | R27: IIBB
M28: =(M30-K30) -> 546.53714 | O28: =O26+O27 -> 0.2 | Q28: =Q26+Q27+Q25 -> 0.1686 | T28: Descuento | U28: Descuento | V28: Descuento
B29: Mini Recuerdo | C29: Choco | D29: Etiqueta | E29: Tarjeta | K29: Costo real | L29: Ganancia | M29: Total | O29: MP | P29: MP | Q29: Ganan MP | T29: 0.05 | U29: 0.1 | V29: 0.15
C30: =C7 -> 224 | D30: =D7 -> 8.5685714 | E30: =Insumos!G12/10 -> 40.7 | K30: =SUM(C30:E30) -> 273.26857 | L30: =M30-K30 -> 546.53714 | M30: =K30*3 -> 819.80571 | O30: =ROUNDUP(P30, -1) -> 990 | P30: =M30+(M30*O28) -> 983.76686 | Q30: =O30-(O30*Q28)-K30 -> 549.81743 | T30: 50 | U30: 100 | V30: 200
T31: Costo total | U31: Costo total | V31: Costo total
T32: =$K$30*T30 -> 13663.429 | U32: =$K$30*U30 -> 27326.857 | V32: =$K$30*V30 -> 54653.714
T33: MP | U33: MP | V33: MP
O34: descuento | Q34: IIBB | T34: =($O30*T30)-(($O30*T30)*T29) -> 47025 | U34: =($O30*U30)-(($O30*U30)*U29) -> 89100 | V34: =($O30*V30)-(($O30*V30)*V29) -> 168300
O35: 0.1 | Q35: 0.06 | T35: =T34/T30 -> 940.5 | U35: =U34/U30 -> 891 | V35: =V34/V30 -> 841.5
O36: Transf | Q36: G. Transf | T36: Ganancia MP | U36: Ganancia MP | V36: Ganancia MP
O37: =O30-(O30*O35) -> 891 | Q37: =(O37-(O37*Q35))-K30 -> 564.27143 | T37: =(T34-T32)-(T34*$Q$28) -> 25433.156 | U37: =(U34-U32)-(U34*$Q$28) -> 46750.883 | V37: =(V34-V32)-(V34*$Q$28) -> 85270.906
T38: =T37/T30 -> 508.66313 | U38: =U37/U30 -> 467.50883 | V38: =V37/V30 -> 426.35453
T39: Transf | U39: Transf | V39: Transf
T40: =T34-(T34*T41) -> 42322.5 | U40: =U34-(U34*U41) -> 80190 | V40: =V34-(V34*V41) -> 151470
T41: =$O$12 -> 0.1 | U41: =$O$12 -> 0.1 | V41: =$O$12 -> 0.1
...

Sheet $ Mercado Libre $
E1: 1100 | G1: 2300 | I1: 2810 | K1: 6300 | M1: 1400 | N1: 33000 | O1: 613000
C2: Producto | D2: Unidades | E2: costo unidad | F2: COSTO TOTAL | G2: $ Venta Por Unidad | H2: Venta Total | I2: % | J2: 0.02 | L2: Envio | M2: Costo extra | N2: $ EN ML | O2: Cuanto queda | P2: Impuesto | Q2: $ C/U | R2: Cuanto $ Afuera
G3: Por unidad | M3: 15000 | P3: 0.06
M4: 25000 | R4: $ Transf | S4: Packaging
G5: Chocos Sueltos
C6: Chocos Sueltos | D6: 10 | E6: ='Coloniales S.C'!K7 -> 232.56857 | F6: =E6*D6 -> 2325.6857 | G6: ='Coloniales S.C'!M7 -> 651.192 | H6: =(G6*D6)+S6 -> 8511.92 | I6: 0.43 | J6: 0.145 | K6: =N6*J6 -> 1764.9466 | M6: =IF(N6<=$M$3,$E$1,IF(N6<=$M$4,$G$1,IF(N6<=$N$1,$I$1,0))) -> 1100 | N6: =H6+(H6*I6) -> 12172.046 | O6: =N6 - K6 - P7 - M6-L6 -> 8576.7763 | R6: =G6*D6 -> 6511.92 | S6: 2000
